Workbook
Name aa: #REF!
Name aa: #REF!
Name aa: #REF!
Name aa: #REF!
Name aa: #REF!
Name ABONO: #REF!
Name B: #REF!
Name Bono: '[1]Summary-Trend'!$C$149:$D$152
Name Bono: '[1]Summary-Trend'!$C$149:$D$152
Name Bono: '[1]Summary-Trend'!$C$149:$D$152
Name Bono: '[1]Summary-Trend'!$C$149:$D$152
Name Bono: #REF!
Name Bonus04: #REF!
Name Bonus04: #REF!
Name Bonus04: #REF!
Name Bonus04: #REF!
Name Bonus04: #REF!
Name carm: #REF!
Name carm: #REF!
Name carm: #REF!
Name carm: #REF!
Name carm: #REF!
Name Cars: #REF!
Name Cars: #REF!
Name Cars: #REF!
Name Cars: #REF!
Name Cars: #REF!
Name CODIGO: #REF!
Name CostoMetro: #REF!
Name CostoMetro: #REF!
Name CostoMetro: #REF!
Name CostoMetro: #REF!
Name CostoMetro: #REF!
Name cpi: '[1]Summary-Trend'!$D$142
Name cpi: '[1]Summary-Trend'!$D$142
Name cpi: '[1]Summary-Trend'!$D$142
Name cpi: '[1]Summary-Trend'!$D$142
Name cpi: #REF!
Name dates: #REF!
Name FECHA: #REF!
Name fiscal: #REF!
Name gentemetro: #REF!
Name gentemetro: #REF!
Name gentemetro: #REF!
Name gentemetro: #REF!
Name gentemetro: #REF!
Name Groceries_Limit: #REF!
Name Groceries_Limit: #REF!
Name Groceries_Limit: #REF!
Name Groceries_Limit: #REF!
Name Groceries_Limit: #REF!
Name imss: #REF!
Name IPC: Finanzas!$V$1
Name IPC: Ops!$V$1
Name IPC: RH!$V$1
Name IPC: Tech!$V$1
Name IPC: #REF!
Name minimum_wage04: #REF!
Name Months: #REF!
Name s: #REF!

Sheet Budget
B2: BUDGET:
C3: Ene | D3: Feb | E3: Mar | F3: Abr | G3: May | H3: Jun | I3: Jul | J3: Ago | K3: Sep | L3: Oct | M3: Nov | N3: Dic | O3: TOTAL 2026
B4: Net Sales | C4: 12435 | D4: 10935 | E4: 10785 | F4: 10785 | G4: 14785 | H4: 14285 | I4: 14284 | J4: 12884 | K4: 13884 | L4: 10279 | M4: 10279 | N4: 9659 | O4: =SUM(C4:N4) -> 145279
B5: COGS | C5: =+C6+C9 -> 4609.5207 | D5: =+D6+D9 -> 4685.6245 | E5: =+E6+E9 -> 5672.9583 | F5: =+F6+F9 -> 6568.9221 | G5: =+G6+G9 -> 6647.5647 | H5: =+H6+H9 -> 6185.2249 | I5: =+I6+I9 -> 5339.9669 | J5: =+J6+J9 -> 4804.9404 | ... N5: =+N6+N9 -> 5507.9694 | O5: =SUM(C5:N5) -> 65142.76
B6: Payroll | C6: =SUM(C7:C8) -> 2077.6307 | D6: =SUM(D7:D8) -> 2077.6307 | E6: =SUM(E7:E8) -> 2226.5921 | F6: =SUM(F7:F8) -> 2229.6252 | G6: =SUM(G7:G8) -> 2229.6252 | H6: =SUM(H7:H8) -> 2229.6252 | I6: =SUM(I7:I8) -> 2229.6252 | J6: =SUM(J7:J8) -> 2229.6252 | ... N6: =SUM(N7:N8) -> 2389.8165 | O6: =SUM(C6:N6) -> 26608.671
B7: Dir. Ops | C7: =+Ops!D45/1000 -> 1598.9449 | D7: =+Ops!E45/1000 -> 1598.9449 | E7: =+Ops!F45/1000 -> 1747.9063 | F7: =+Ops!G45/1000 -> 1750.2412 | G7: =+Ops!H45/1000 -> 1750.2412 | H7: =+Ops!I45/1000 -> 1750.2412 | I7: =+Ops!J45/1000 -> 1750.2412 | J7: =+Ops!K45/1000 -> 1750.2412 | ... N7: =+Ops!O45/1000 -> 1910.4326 | O7: =SUM(C7:N7) -> 20858.158
B8: Dir. Tech | C8: =+Tech!D45/1000 -> 478.68584 | D8: =+Tech!E45/1000 -> 478.68584 | E8: =+Tech!F45/1000 -> 478.68584 | F8: =+Tech!G45/1000 -> 479.38395 | G8: =+Tech!H45/1000 -> 479.38395 | H8: =+Tech!I45/1000 -> 479.38395 | I8: =+Tech!J45/1000 -> 479.38395 | J8: =+Tech!K45/1000 -> 479.38395 | ... N8: =+Tech!O45/1000 -> 479.38395 | O8: =SUM(C8:N8) -> 5750.513
B9: Direct cost | C9: =SUM(C10:C11) -> 2531.89 | D9: =SUM(D10:D11) -> 2607.9938 | E9: =SUM(E10:E11) -> 3446.3663 | F9: =SUM(F10:F11) -> 4339.2969 | G9: =SUM(G10:G11) -> 4417.9395 | H9: =SUM(H10:H11) -> 3955.5997 | I9: =SUM(I10:I11) -> 3110.3417 | J9: =SUM(J10:J11) -> 2575.3153 | ... N9: =SUM(N10:N11) -> 3118.1529 | O9: =SUM(C9:N9) -> 38534.089
B10: Dir. Ops | C10: =+Ops!D139/1000 -> 1790.851 | D10: =+Ops!E139/1000 -> 1981.581 | E10: =+Ops!F139/1000 -> 2722.937 | F10: =+Ops!G139/1000 -> 3526.435 | G10: =+Ops!H139/1000 -> 3342.042 | H10: =+Ops!I139/1000 -> 3294.757 | I10: =+Ops!J139/1000 -> 2467.607 | J10: =+Ops!K139/1000 -> 2035.18 | ... N10: =+Ops!O139/1000 -> 2359.198 | O10: =SUM(C10:N10) -> 30246.014
B11: Dir. Tech | C11: =+Tech!D159/1000 -> 741.03905 | D11: =+Tech!E159/1000 -> 626.41285 | E11: =+Tech!F159/1000 -> 723.42925 | F11: =+Tech!G159/1000 -> 812.86193 | G11: =+Tech!H159/1000 -> 1075.8975 | H11: =+Tech!I159/1000 -> 660.84273 | I11: =+Tech!J159/1000 -> 642.73473 | J11: =+Tech!K159/1000 -> 540.13527 | ... N11: =+Tech!O159/1000 -> 758.95487 | O11: =SUM(C11:N11) -> 8288.0748
B12: Gross Margin | C12: =+C4-C5 -> 7825.4793 | D12: =+D4-D5 -> 6249.3755 | E12: =+E4-E5 -> 5112.0417 | F12: =+F4-F5 -> 4216.0779 | G12: =+G4-G5 -> 8137.4353 | H12: =+H4-H5 -> 8099.7751 | I12: =+I4-I5 -> 8944.0331 | J12: =+J4-J5 -> 8079.0596 | ... N12: =+N4-N5 -> 4151.0306 | O12: =SUM(C12:N12) -> 80136.24
B13: SG&A | C13: =+C14+C19 -> 1403.4092 | D13: =+D14+D19 -> 1394.9455 | E13: =+E14+E19 -> 1638.0115 | F13: =+F14+F19 -> 1481.2069 | G13: =+G14+G19 -> 1393.7694 | H13: =+H14+H19 -> 1550.9553 | I13: =+I14+I19 -> 1400.5694 | J13: =+J14+J19 -> 1448.9549 | ... N13: =+N14+N19 -> 1459.1778 | O13: =SUM(C13:N13) -> 17413.299
B14: Payroll | C14: =SUM(C15:C18) -> 1190.4463 | D14: =SUM(D15:D18) -> 1190.4463 | E14: =SUM(E15:E18) -> 1192.8823 | F14: =SUM(F15:F18) -> 1272.9127 | G14: =SUM(G15:G18) -> 1272.9127 | H14: =SUM(H15:H18) -> 1272.9127 | I14: =SUM(I15:I18) -> 1272.9127 | J14: =SUM(J15:J18) -> 1272.9127 | ... N14: =SUM(N15:N18) -> 1272.9127 | O14: =SUM(C14:N14) -> 15029.989
B15: Dir. General | C15: =+Gral!H12/1000 -> 489.5326 | D15: =+C15 -> 489.5326 | E15: =+D15 -> 489.5326 | F15: =+E15 -> 489.5326 | G15: =+F15 -> 489.5326 | H15: =+G15 -> 489.5326 | I15: =+H15 -> 489.5326 | J15: =+I15 -> 489.5326 | K15: =+J15 -> 489.5326 | ... N15: =+M15 -> 489.5326 | O15: =SUM(C15:N15) -> 5874.3913
B16: Dir. Finanzas | C16: =+Finanzas!D45/1000 -> 83.109143 | D16: =+Finanzas!E45/1000 -> 83.109143 | E16: =+Finanzas!F45/1000 -> 83.109143 | F16: =+Finanzas!G45/1000 -> 113.64429 | G16: =+Finanzas!H45/1000 -> 113.64429 | H16: =+Finanzas!I45/1000 -> 113.64429 | I16: =+Finanzas!J45/1000 -> 113.64429 | J16: =+Finanzas!K45/1000 -> 113.64429 | ... N16: =+Finanzas!O45/1000 -> 113.64429 | O16: =SUM(C16:N16) -> 1272.1261
B17: Dir. RH | C17: =+RH!D45/1000 -> 78.701839 | D17: =+RH!E45/1000 -> 78.701839 | E17: =+RH!F45/1000 -> 81.13784 | F17: =+RH!G45/1000 -> 130.63312 | G17: =+RH!H45/1000 -> 130.63312 | H17: =+RH!I45/1000 -> 130.63312 | I17: =+RH!J45/1000 -> 130.63312 | J17: =+RH!K45/1000 -> 130.63312 | ... N17: =+RH!O45/1000 -> 130.63312 | O17: =SUM(C17:N17) -> 1414.2396
B18: Dir. Comercial | C18: =+Comercial!H22/1000 -> 539.10271 | D18: =+C18 -> 539.10271 | E18: =+D18 -> 539.10271 | F18: =+E18 -> 539.10271 | G18: =+F18 -> 539.10271 | H18: =+G18 -> 539.10271 | I18: =+H18 -> 539.10271 | J18: =+I18 -> 539.10271 | K18: =+J18 -> 539.10271 | ... N18: =+M18 -> 539.10271 | O18: =SUM(C18:N18) -> 6469.2326
B19: Indirect cost | C19: =SUM(C20:C23) -> 212.96285 | D19: =SUM(D20:D23) -> 204.49919 | E19: =SUM(E20:E23) -> 445.12919 | F19: =SUM(F20:F23) -> 208.29419 | G19: =SUM(G20:G23) -> 120.85665 | H19: =SUM(H20:H23) -> 278.0426 | I19: =SUM(I20:I23) -> 127.65665 | J19: =SUM(J20:J23) -> 176.0422 | ... N19: =SUM(N20:N23) -> 186.26505 | O19: =SUM(C19:N19) -> 2383.3096
B20: Dir. General | C20: =+'Gtos Gral'!C17/1000 -> 7 | D20: =+'Gtos Gral'!D17/1000 -> 0 | E20: =+'Gtos Gral'!E17/1000 -> 0 | F20: =+'Gtos Gral'!F17/1000 -> 7 | G20: =+'Gtos Gral'!G17/1000 -> 6 | H20: =+'Gtos Gral'!H17/1000 -> 20 | I20: =+'Gtos Gral'!I17/1000 -> 7 | J20: =+'Gtos Gral'!J17/1000 -> 0 | ... N20: =+'Gtos Gral'!N17/1000 -> 20 | O20: =SUM(C20:N20) -> 74
B21: Dir. Finanzas | C21: =+Finanzas!D137/1000 -> 70.68272 | D21: =+Finanzas!E137/1000 -> 124.71186 | E21: =+Finanzas!F137/1000 -> 128.21186 | F21: =+Finanzas!G137/1000 -> 124.71186 | G21: =+Finanzas!H137/1000 -> 11.57432 | H21: =+Finanzas!I137/1000 -> 167.26027 | I21: =+Finanzas!J137/1000 -> 11.57432 | J21: =+Finanzas!K137/1000 -> 104.65187 | ... N21: =+Finanzas!O137/1000 -> 74.18272 | O21: =SUM(C21:N21) -> 914.89316
B22: Dir. RH | C22: =+RH!D184/1000 -> 135.28013 | D22: =+RH!E184/1000 -> 76.78733 | E22: =+RH!F184/1000 -> 265.01733 | F22: =+RH!G184/1000 -> 61.58233 | G22: =+RH!H184/1000 -> 73.18233 | H22: =+RH!I184/1000 -> 78.48233 | I22: =+RH!J184/1000 -> 72.18233 | J22: =+RH!K184/1000 -> 65.39033 | ... N22: =+RH!O184/1000 -> 92.08233 | O22: =SUM(C22:N22) -> 1198.7165
B23: Dir. Comercial | C23: 0 | D23: =+'Gtos Com'!K2/1000 -> 3 | E23: =SUM('Gtos Com'!K3:K14)/1000 -> 51.9 | F23: =SUM('Gtos Com'!K15:K19)/1000 -> 15 | G23: =SUM('Gtos Com'!K20:K25)/1000 -> 30.1 | H23: =SUM('Gtos Com'!K26:K28)/1000 -> 12.3 | I23: =SUM('Gtos Com'!K29:K33)/1000 -> 36.9 | J23: =SUM('Gtos Com'!K34:K35)/1000 -> 6 | K23: =SUM('Gtos Com'!K36)/1000 -> 9.9 | L23: =SUM('Gtos Com'!K37:K39)/1000 -> 30.6 | M23: 0 | N23: 0 | O23: =SUM(C23:N23) -> 195.7
B24: Dividends | C24: 1667 | D24: 1667 | E24: 1667 | F24: 1667 | G24: 1667 | H24: 1667 | I24: 1667 | J24: 1667 | K24: 1667 | L24: 1667 | M24: 1667 | N24: 1667 | O24: =SUM(C24:N24) -> 20004
B25: Taxes | C25: 126 | D25: 126 | E25: 126 | F25: 126 | G25: 253 | H25: 253 | I25: 253 | J25: 253 | K25: 253 | L25: 253 | M25: 253 | N25: 253 | O25: =SUM(C25:N25) -> 2528
B26: Net Income | C26: =+C12-C13-C24-C25 -> 4629.0701 | D26: =+D12-D13-D24-D25 -> 3061.43 | E26: =+E12-E13-E24-E25 -> 1681.0302 | F26: =+F12-F13-F24-F25 -> 941.87098 | G26: =+G12-G13-G24-G25 -> 4823.6659 | H26: =+H12-H13-H24-H25 -> 4628.8198 | I26: =+I12-I13-I24-I25 -> 5623.4637 | J26: =+J12-J13-J24-J25 -> 4710.1046 | ... M26: =+M12-M13-M24-M25 -> 2099.0516 | N26: =+N4-N5-N13-N24 -> 1024.8528 | O26: =SUM(C26:N26) -> 40443.941
B28: ROLLING FORECAST:
C29: Act | D29: Act | E29: Act | F29: Act | G29: Fcst | H29: Fcst | I29: Fcst | J29: Fcst | K29: Fcst | L29: Fcst | M29: Fcst | N29: Fcst
C30: Ene | D30: Feb | E30: Mar | F30: Abr | G30: May | H30: Jun | I30: Jul | J30: Ago | K30: Sep | L30: Oct | M30: Nov | N30: Dic | O30: TOTAL 2026
B31: Net Sales | C31: 5872 | D31: 13957 | E31: 15189 | F31: 16171 | G31: 16635 | H31: 12368 | I31: 12508 | J31: 11018 | K31: 15040 | L31: 14425 | M31: 12950 | N31: 10862 | O31: =SUM(C31:N31) -> 156995
B32: COGS | C32: =+C33+C36 -> 0 | D32: =+D33+D36 -> 0 | E32: =+E33+E36 -> 0 | F32: =+F33+F36 -> 5744 | G32: =+G33+G36 -> 6647.5647 | H32: =+H33+H36 -> 6185.2249 | I32: =+I33+I36 -> 5339.9669 | J32: =+J33+J36 -> 4804.9404 | ... N32: =+N33+N36 -> 5507.9694 | O32: =SUM(C32:N32) -> 49349.734
B33: Payroll | C33: =SUM(C34:C35) -> 0 | D33: =SUM(D34:D35) -> 0 | E33: =SUM(E34:E35) -> 0 | F33: =SUM(F34:F35) -> 1924 | G33: =SUM(G34:G35) -> 2229.6252 | H33: =SUM(H34:H35) -> 2229.6252 | I33: =SUM(I34:I35) -> 2229.6252 | J33: =SUM(J34:J35) -> 2229.6252 | ... N33: =SUM(N34:N35) -> 2389.8165 | O33: =SUM(C33:N33) -> 19921.193
B34: Dir. Ops | F34: =782+760 -> 1542 | G34: =+G7 -> 1750.2412 | H34: =+H7 -> 1750.2412 | I34: =+I7 -> 1750.2412 | J34: =+J7 -> 1750.2412 | K34: =+K7 -> 1750.2412 | L34: =+L7 -> 1750.2412 | M34: =+M7 -> 1750.2412 | N34: =+N7 -> 1910.4326 | O34: =SUM(C34:N34) -> 15704.121
B35: Dir. Tech | F35: 382 | G35: =+G8 -> 479.38395 | H35: =+H8 -> 479.38395 | I35: =+I8 -> 479.38395 | J35: =+J8 -> 479.38395 | K35: =+K8 -> 479.38395 | L35: =+L8 -> 479.38395 | M35: =+M8 -> 479.38395 | N35: =+N8 -> 479.38395 | O35: =SUM(C35:N35) -> 4217.0716
B36: Direct cost | C36: =SUM(C37:C38) -> 0 | D36: =SUM(D37:D38) -> 0 | E36: =SUM(E37:E38) -> 0 | F36: =SUM(F37:F38) -> 3820 | G36: =SUM(G37:G38) -> 4417.9395 | H36: =SUM(H37:H38) -> 3955.5997 | I36: =SUM(I37:I38) -> 3110.3417 | J36: =SUM(J37:J38) -> 2575.3153 | ... N36: =SUM(N37:N38) -> 3118.1529 | O36: =SUM(C36:N36) -> 29428.542
B37: Dir. Ops | F37: 2903 | G37: =+G10 -> 3342.042 | H37: =+H10 -> 3294.757 | I37: =+I10 -> 2467.607 | J37: =+J10 -> 2035.18 | K37: =+K10 -> 2549.503 | L37: =+L10 -> 2172.411 | M37: =+M10 -> 2003.512 | N37: =+N10 -> 2359.198 | O37: =SUM(C37:N37) -> 23127.21
B38: Dir. Tech | F38: 917 | G38: =+G11 -> 1075.8975 | H38: =+H11 -> 660.84273 | I38: =+I11 -> 642.73473 | J38: =+J11 -> 540.13527 | K38: =+K11 -> 484.14047 | L38: =+L11 -> 576.93567 | M38: =+M11 -> 644.69047 | N38: =+N11 -> 758.95487 | O38: =SUM(C38:N38) -> 6301.3317
B39: Gross Margin | C39: =+C31-C32 -> 5872 | D39: =+D31-D32 -> 13957 | E39: =+E31-E32 -> 15189 | F39: =+F31-F32 -> 10427 | G39: =+G31-G32 -> 9987.4353 | H39: =+H31-H32 -> 6182.7751 | I39: =+I31-I32 -> 7168.0331 | J39: =+J31-J32 -> 6213.0596 | ... N39: =+N31-N32 -> 5354.0306 | O39: =SUM(C39:N39) -> 107645.27
B40: SG&A | C40: =+C41+C46 -> 0 | D40: =+D41+D46 -> 0 | E40: =+E41+E46 -> 0 | F40: =+F41+F46 -> 2399.3055 | G40: =+G41+G46 -> 1393.7694 | H40: =+H41+H46 -> 1550.9553 | I40: =+I41+I46 -> 1400.5694 | J40: =+J41+J46 -> 1448.9549 | ... N40: =+N41+N46 -> 1459.1778 | O40: =SUM(C40:N40) -> 13895.032
B41: Payroll | C41: =SUM(C42:C45) -> 0 | D41: =SUM(D42:D45) -> 0 | E41: =SUM(E42:E45) -> 0 | F41: =SUM(F42:F45) -> 1118.8031 | G41: =SUM(G42:G45) -> 1272.9127 | H41: =SUM(H42:H45) -> 1272.9127 | I41: =SUM(I42:I45) -> 1272.9127 | J41: =SUM(J42:J45) -> 1272.9127 | ... N41: =SUM(N42:N45) -> 1272.9127 | O41: =SUM(C41:N41) -> 11302.105
B42: Dir. General | F42: =(+'[2]IS ABR 26'!$C$15+Gral!I9+Gral!J9+Gral!N9)/1000 -> 359.49606 | G42: =+G15 -> 489.5326 | H42: =+H15 -> 489.5326 | I42: =+I15 -> 489.5326 | J42: =+J15 -> 489.5326 | K42: =+K15 -> 489.5326 | L42: =+L15 -> 489.5326 | M42: =+M15 -> 489.5326 | N42: =+N15 -> 489.5326 | O42: =SUM(C42:N42) -> 4275.7569
...

Sheet Ops
C1: PS PROCESO SEGURO, SC | D1: Centro de Costos: | E1: CC | F1: UNIDAD | V1: 0.0368 | W1: % DE INCREMENTO A PARTIR DE ENERO
D2: 0 | E2: =+D2+1 -> 1 | F2: =+E2+1 -> 2 | G2: =+F2+1 -> 3 | H2: =+G2+1 -> 4 | I2: =+H2+1 -> 5 | J2: =+I2+1 -> 6 | K2: =+J2+1 -> 7 | L2: =+K2+1 -> 8 | ... P2: =+O2+1 -> 12
C3: Budget 2026 Expenses | D3: Enero | E3: Febrero | F3: Marzo | G3: Abril | H3: Mayo | I3: Junio | J3: Julio | K3: Agosto | L3: Septiembre | M3: Octubre | N3: Noviembre | O3: Diciembre | P3: Total | R3: %
C4: Mx ps. | D4: Budget 26 | E4: Budget 26 | F4: Budget 26 | G4: Budget 26 | H4: Budget 26 | I4: Budget 26 | J4: Budget 26 | K4: Budget 26 | L4: Budget 26 | M4: Budget 26 | N4: Budget 26 | O4: Budget 26 | P4: Budget 26 | R4: of Total
A6: CUENTA | B6: SUBCUENTA | C6: HEAD COUNT | D6: =$D$238 -> 85 | E6: =$D$238 -> 85 | F6: =$D$238 -> 85 | G6: =$D$238 -> 85 | H6: =$D$238 -> 85 | I6: =$D$238 -> 85 | J6: =$D$238 -> 85 | K6: =$D$238 -> 85 | ... O6: =$D$238 -> 85 | P6: =+O6 -> 85
C8: SUELDOS Y SALARIOS | D8: =+F238 -> 1250250.1 | E8: =+D8 -> 1250250.1 | F8: =+E8 -> 1250250.1 | G8: =+$F$238 -> 1250250.1 | H8: =+$F$238 -> 1250250.1 | I8: =+$F$238 -> 1250250.1 | J8: =+$F$238 -> 1250250.1 | K8: =+$F$238 -> 1250250.1 | L8: =+$F$238 -> 1250250.1 | M8: =+$F$238 -> 1250250.1 | N8: =+$F$238 -> 1250250.1 | O8: =+$F$238 -> 1250250.1 | P8: =+SUM(D8:O8) -> 15003001 | R8: =+IF(P8=0,0,P8/$P$139) -> 0.29357684
C9: Beneficios
C10: VALES DE DESPENSA | D10: =+$S$238 -> 0 | E10: =+$S$238 -> 0 | F10: =+$S$238 -> 0 | G10: =+$S$238*(IPC+1) -> 0 | H10: =+$S$238*(IPC+1) -> 0 | I10: =+$S$238*(IPC+1) -> 0 | J10: =+$S$238*(IPC+1) -> 0 | K10: =+$S$238*(IPC+1) -> 0 | L10: =+$S$238*(IPC+1) -> 0 | M10: =+$S$238*(IPC+1) -> 0 | N10: =+$S$238*(IPC+1) -> 0 | O10: =+$S$238*(IPC+1) -> 0 | P10: =+SUM(D10:O10) -> 0 | R10: =+IF(P10=0,0,P10/$P$139) -> 0
C11: AGUINALDO | D11: =+$O$238 -> 52093.754 | E11: =+$O$238 -> 52093.754 | F11: =+$O$238 -> 52093.754 | G11: =+$O$238*(IPC+1) -> 54010.804 | H11: =+$O$238*(IPC+1) -> 54010.804 | I11: =+$O$238*(IPC+1) -> 54010.804 | J11: =+$O$238*(IPC+1) -> 54010.804 | K11: =+$O$238*(IPC+1) -> 54010.804 | L11: =+$O$238*(IPC+1) -> 54010.804 | M11: =+$O$238*(IPC+1) -> 54010.804 | N11: =+$O$238*(IPC+1) -> 54010.804 | O11: =+$O$238*(IPC+1) -> 54010.804 | P11: =+SUM(D11:O11) -> 642378.5 | R11: =+IF(P11=0,0,P11/$P$139) -> 0.012569982
C12: BONOS | D12: 0 | E12: 0 | F12: =100000+22300 -> 122300 | G12: =100000+22300 -> 122300 | H12: =100000+22300 -> 122300 | I12: =100000+22300 -> 122300 | J12: =100000+22300 -> 122300 | K12: =100000+22300 -> 122300 | L12: =100000+22300 -> 122300 | M12: =100000+22300 -> 122300 | N12: =100000+22300 -> 122300 | O12: =100000+22300+131520 -> 253820 | P12: =+SUM(D12:O12) -> 1354520 | R12: =+IF(P12=0,0,P12/$P$139) -> 0.026505077
C13: COMPENSACIONES | D13: =+$Q$238 -> 0 | E13: =+$Q$238 -> 0 | F13: =+$Q$238 -> 0 | G13: =+$Q$238*(IPC+1) -> 0 | H13: =+$Q$238*(IPC+1) -> 0 | I13: =+$Q$238*(IPC+1) -> 0 | J13: =+$Q$238*(IPC+1) -> 0 | K13: =+$Q$238*(IPC+1) -> 0 | L13: =+$Q$238*(IPC+1) -> 0 | M13: =+$Q$238*(IPC+1) -> 0 | N13: =+$Q$238*(IPC+1) -> 0 | O13: =+$Q$238*(IPC+1) -> 0 | P13: =+SUM(D13:O13) -> 0 | R13: =+IF(P13=0,0,P13/$P$139) -> 0
C14: DIAS FESTIVOS | D14: =+$L$238 -> 0 | E14: =+$L$238 -> 0 | F14: =+$L$238 -> 0 | G14: =+$L$238*(IPC+1) -> 0 | H14: =+$L$238*(IPC+1) -> 0 | I14: =+$L$238*(IPC+1) -> 0 | J14: =+$L$238*(IPC+1) -> 0 | K14: =+$L$238*(IPC+1) -> 0 | L14: =+$L$238*(IPC+1) -> 0 | M14: =+$L$238*(IPC+1) -> 0 | N14: =+$L$238*(IPC+1) -> 0 | O14: =+$L$238*(IPC+1) -> 0 | P14: =+SUM(D14:O14) -> 0 | R14: =+IF(P14=0,0,P14/$P$139) -> 0
C15: HORAS EXTRAS | D15: =+$I$238 -> 0 | E15: =+$I$238 -> 0 | F15: =+$I$238 -> 0 | G15: =+$I$238*(IPC+1) -> 0 | H15: =+$I$238*(IPC+1) -> 0 | I15: =+$I$238*(IPC+1) -> 0 | J15: =+$I$238*(IPC+1) -> 0 | K15: =+$I$238*(IPC+1) -> 0 | L15: =+$I$238*(IPC+1) -> 0 | M15: =+$I$238*(IPC+1) -> 0 | N15: =+$I$238*(IPC+1) -> 0 | O15: =+$I$238*(IPC+1) -> 0 | P15: =+SUM(D15:O15) -> 0 | R15: =+IF(P15=0,0,P15/$P$139) -> 0
C16: INDEMNIZACIONES (DESPIDO) | D16: 0 | E16: 0 | F16: 0 | G16: 0 | H16: 0 | I16: 0 | J16: 0 | K16: 0 | L16: 0 | M16: 0 | N16: 0 | O16: 0 | P16: =+SUM(D16:O16) -> 0 | R16: =+IF(P16=0,0,P16/$P$139) -> 0
C17: PRIMA DE ANTIGUEDAD | D17: 0 | E17: 0 | F17: 0 | G17: 0 | H17: 0 | I17: 0 | J17: 0 | K17: 0 | L17: 0 | M17: 0 | N17: 0 | O17: 0 | P17: =+SUM(D17:O17) -> 0 | R17: =+IF(P17=0,0,P17/$P$139) -> 0
C18: PRIMA DOMINICAL | D18: 0 | E18: 0 | F18: 0 | G18: 0 | H18: 0 | I18: 0 | J18: 0 | K18: 0 | L18: 0 | M18: 0 | N18: 0 | O18: 0 | P18: =+SUM(D18:O18) -> 0 | R18: =+IF(P18=0,0,P18/$P$139) -> 0
C19: PRIMA VACACIONAL | D19: =+$R$238 -> 10418.751 | E19: =+$R$238 -> 10418.751 | F19: =+$R$238 -> 10418.751 | G19: =+$R$238 -> 10418.751 | H19: =+$R$238 -> 10418.751 | I19: =+$R$238 -> 10418.751 | J19: =+$R$238 -> 10418.751 | K19: =+$R$238 -> 10418.751 | ... O19: =+$R$238 -> 10418.751 | P19: =+SUM(D19:O19) -> 125025.01 | R19: =+IF(P19=0,0,P19/$P$139) -> 0.0024464736 | W19: =+O19*(IPC+1) -> 10802.161
C20: PREMIO DE ASISTENCIA | D20: 0 | E20: 0 | F20: 0 | G20: 0 | H20: 0 | I20: 0 | J20: 0 | K20: 0 | L20: 0 | M20: 0 | N20: 0 | O20: 0 | P20: =+SUM(D20:O20) -> 0 | R20: =+IF(P20=0,0,P20/$P$139) -> 0
C21: PREMIO DE PUNTUALIDAD | D21: 0 | E21: 0 | F21: 0 | G21: 0 | H21: 0 | I21: 0 | J21: 0 | K21: 0 | L21: 0 | M21: 0 | N21: 0 | O21: 0 | P21: =+SUM(D21:O21) -> 0 | R21: =+IF(P21=0,0,P21/$P$139) -> 0
C22: VACACIONES | D22: =+$P$238 -> 0 | E22: =+$P$238 -> 0 | F22: =+$P$238 -> 0 | G22: =+$P$238 -> 0 | H22: =+$P$238 -> 0 | I22: =+$P$238 -> 0 | J22: =+$P$238 -> 0 | K22: =+$P$238 -> 0 | ... O22: =+$P$238 -> 0 | P22: =+SUM(D22:O22) -> 0 | R22: =+IF(P22=0,0,P22/$P$139) -> 0
C23: GRATIFICACIONES | D23: 0 | E23: 0 | F23: 0 | G23: 0 | H23: 0 | I23: 0 | J23: 0 | K23: 0 | L23: 0 | M23: 0 | N23: 0 | O23: 0 | P23: =+SUM(D23:O23) -> 0 | R23: =+IF(P23=0,0,P23/$P$139) -> 0
C24: HORAS EXTRAS TRIPLES | D24: =+$J$238 -> 0 | E24: =+$J$238 -> 0 | F24: =+$J$238 -> 0 | G24: =+$J$238*(IPC+1) -> 0 | H24: =+$J$238*(IPC+1) -> 0 | I24: =+$J$238*(IPC+1) -> 0 | J24: =+$J$238*(IPC+1) -> 0 | K24: =+$J$238*(IPC+1) -> 0 | L24: =+$J$238*(IPC+1) -> 0 | M24: =+$J$238*(IPC+1) -> 0 | N24: =+$J$238*(IPC+1) -> 0 | O24: =+$J$238*(IPC+1) -> 0 | P24: =+SUM(D24:O24) -> 0 | R24: =+IF(P24=0,0,P24/$P$139) -> 0
C25: FONDO DE AHORRO | D25: =+$M$238 -> 0 | E25: =+$M$238 -> 0 | F25: =+$M$238 -> 0 | G25: =+$M$238*(IPC+1) -> 0 | H25: =+$M$238*(IPC+1) -> 0 | I25: =+$M$238*(IPC+1) -> 0 | J25: =+$M$238*(IPC+1) -> 0 | K25: =+$M$238*(IPC+1) -> 0 | L25: =+$M$238*(IPC+1) -> 0 | M25: =+$M$238*(IPC+1) -> 0 | N25: =+$M$238*(IPC+1) -> 0 | O25: =+$M$238*(IPC+1) -> 0 | P25: =+SUM(D25:O25) -> 0 | R25: =+IF(P25=0,0,P25/$P$139) -> 0
C26: COMISIONES SOBRE VENTAS | D26: 0 | E26: 0 | F26: 0 | G26: 0 | H26: 0 | I26: 0 | J26: 0 | K26: 0 | L26: 0 | M26: 0 | N26: 0 | O26: 0 | P26: =+SUM(D26:O26) -> 0 | R26: =+IF(P26=0,0,P26/$P$139) -> 0
C27: DESCANSO LABORADO | D27: =+$K$238 -> 0 | E27: =+$K$238 -> 0 | F27: =+$K$238 -> 0 | G27: =+$K$238*(IPC+1) -> 0 | H27: =+$K$238*(IPC+1) -> 0 | I27: =+$K$238*(IPC+1) -> 0 | J27: =+$K$238*(IPC+1) -> 0 | K27: =+$K$238*(IPC+1) -> 0 | L27: =+$K$238*(IPC+1) -> 0 | M27: =+$K$238*(IPC+1) -> 0 | N27: =+$K$238*(IPC+1) -> 0 | O27: =+$K$238*(IPC+1) -> 0 | P27: =+SUM(D27:O27) -> 0 | R27: =+IF(P27=0,0,P27/$P$139) -> 0
C28: VALES RESTAURANTE | D28: =+$H$238 -> 0 | E28: =+$H$238 -> 0 | F28: =+$H$238 -> 0 | G28: =+$H$238*(IPC+1) -> 0 | H28: =+$H$238*(IPC+1) -> 0 | I28: =+$H$238*(IPC+1) -> 0 | J28: =+$H$238*(IPC+1) -> 0 | K28: =+$H$238*(IPC+1) -> 0 | L28: =+$H$238*(IPC+1) -> 0 | M28: =+$H$238*(IPC+1) -> 0 | N28: =+$H$238*(IPC+1) -> 0 | O28: =+$H$238*(IPC+1) -> 0 | P28: =+SUM(D28:O28) -> 0 | R28: =+IF(P28=0,0,P28/$P$139) -> 0
C29: INDEMNIZACIONES (RETIRO) | D29: 0 | E29: 0 | F29: 0 | G29: 0 | H29: 0 | I29: 0 | J29: 0 | K29: 0 | L29: 0 | M29: 0 | N29: 0 | O29: 0 | P29: =+SUM(D29:O29) -> 0
C30: BONO DE AUTO | D30: 0 | E30: 0 | F30: 0 | G30: 0 | H30: 0 | I30: 0 | J30: 0 | K30: 0 | L30: 0 | M30: 0 | N30: 0 | O30: 0 | P30: =+SUM(D30:O30) -> 0
C31: TOTAL BENEFICIOS | D31: =SUM(D8:D30)-D22 -> 1312762.6 | E31: =SUM(E8:E30)-E22 -> 1312762.6 | F31: =SUM(F8:F30)-F22 -> 1435062.6 | G31: =SUM(G8:G30)-G22 -> 1436979.7 | H31: =SUM(H8:H30)-H22 -> 1436979.7 | I31: =SUM(I8:I30)-I22 -> 1436979.7 | J31: =SUM(J8:J30)-J22 -> 1436979.7 | K31: =SUM(K8:K30)-K22 -> 1436979.7 | ... P31: =SUM(P8:P30)-P22 -> 17124925 | R31: =+IF(P31=0,0,P31/$P$139) -> 0.33509837
C33: Impuestos + Comisiones
C34: IMSS PATRONAL | D34: 0 | E34: 0 | F34: 0 | G34: 0 | H34: 0 | I34: 0 | J34: 0 | K34: 0 | L34: 0 | M34: 0 | N34: 0 | O34: 0 | P34: =+SUM(D34:O34) -> 0 | R34: =+IF(P34=0,0,P34/$P$139) -> 0
C35: APORTACIONES AL INFONAVIT | D35: 0 | E35: 0 | F35: 0 | G35: 0 | H35: 0 | I35: 0 | J35: 0 | K35: 0 | L35: 0 | M35: 0 | N35: 0 | O35: 0 | P35: =+SUM(D35:O35) -> 0 | R35: =+IF(P35=0,0,P35/$P$139) -> 0
C36: SAR | D36: 0 | E36: 0 | F36: 0 | G36: 0 | H36: 0 | I36: 0 | J36: 0 | K36: 0 | L36: 0 | M36: 0 | N36: 0 | O36: 0 | P36: =+SUM(D36:O36) -> 0 | R36: =+IF(P36=0,0,P36/$P$139) -> 0
C37: 5% INFONAVIT | D37: 0 | E37: 0 | F37: 0 | G37: 0 | H37: 0 | I37: 0 | J37: 0 | K37: 0 | L37: 0 | M37: 0 | N37: 0 | O37: 0 | P37: =+SUM(D37:O37) -> 0 | R37: =+IF(P37=0,0,P37/$P$139) -> 0
C38: RETIRO CESANTIA Y VEJEZ | D38: 0 | E38: 0 | F38: 0 | G38: 0 | H38: 0 | I38: 0 | J38: 0 | K38: 0 | L38: 0 | M38: 0 | N38: 0 | O38: 0 | P38: =+SUM(D38:O38) -> 0 | R38: =+IF(P38=0,0,P38/$P$139) -> 0
C39: DIFERENCIAS INFONAVIT | D39: 0 | E39: 0 | F39: 0 | G39: 0 | H39: 0 | I39: 0 | J39: 0 | K39: 0 | L39: 0 | M39: 0 | N39: 0 | O39: 0 | P39: =+SUM(D39:O39) -> 0 | R39: =+IF(P39=0,0,P39/$P$139) -> 0
C40: DIFERENCIAS I.M.S.S. | D40: 0 | E40: 0 | F40: 0 | G40: 0 | H40: 0 | I40: 0 | J40: 0 | K40: 0 | L40: 0 | M40: 0 | N40: 0 | O40: 0 | P40: =+SUM(D40:O40) -> 0 | R40: =+IF(P40=0,0,P40/$P$139) -> 0
C41: IVA | D41: =SUM(+D31+D42)*0.16 -> 220544.12 | E41: =SUM(+E31+E42)*0.16 -> 220544.12 | F41: =SUM(+F31+F42)*0.16 -> 241090.52 | G41: =SUM(+G31+G42)*0.16 -> 241412.58 | H41: =SUM(+H31+H42)*0.16 -> 241412.58 | I41: =SUM(+I31+I42)*0.16 -> 241412.58 | J41: =SUM(+J31+J42)*0.16 -> 241412.58 | K41: =SUM(+K31+K42)*0.16 -> 241412.58 | ... O41: =SUM(+O31+O42)*0.16 -> 263507.94 | P41: =+SUM(D41:O41) -> 2876987.3 | R41: =+IF(P41=0,0,P41/$P$139) -> 0.056296526
C42: Comisión | D42: =+D31*0.05 -> 65638.13 | E42: =+E31*0.05 -> 65638.13 | F42: =+F31*0.05 -> 71753.13 | G42: =+G31*0.05 -> 71848.983 | H42: =+H31*0.05 -> 71848.983 | I42: =+I31*0.05 -> 71848.983 | J42: =+J31*0.05 -> 71848.983 | K42: =+K31*0.05 -> 71848.983 | ... O42: =+O31*0.05 -> 78424.983 | P42: =+SUM(D42:O42) -> 856246.23 | R42: =+IF(P42=0,0,P42/$P$139) -> 0.016754918
C43: TOTAL IMPUESTOS | D43: =SUM(D34:D42) -> 286182.25 | E43: =SUM(E34:E42) -> 286182.25 | F43: =SUM(F34:F42) -> 312843.65 | G43: =SUM(G34:G42) -> 313261.56 | H43: =SUM(H34:H42) -> 313261.56 | I43: =SUM(I34:I42) -> 313261.56 | J43: =SUM(J34:J42) -> 313261.56 | K43: =SUM(K34:K42) -> 313261.56 | ... P43: =SUM(P34:P42) -> 3733233.6 | R43: =+IF(P43=0,0,P43/$P$139) -> 0.073051444
...

Sheet Tech
C1: PS PROCESO SEGURO, SC | D1: Centro de Costos: | E1: CC | F1: UNIDAD | V1: 0.0368 | W1: % DE INCREMENTO A PARTIR DE ENERO
D2: 0 | E2: =+D2+1 -> 1 | F2: =+E2+1 -> 2 | G2: =+F2+1 -> 3 | H2: =+G2+1 -> 4 | I2: =+H2+1 -> 5 | J2: =+I2+1 -> 6 | K2: =+J2+1 -> 7 | L2: =+K2+1 -> 8 | ... P2: =+O2+1 -> 12
C3: Budget 2026 Expenses | D3: Enero | E3: Febrero | F3: Marzo | G3: Abril | H3: Mayo | I3: Junio | J3: Julio | K3: Agosto | L3: Septiembre | M3: Octubre | N3: Noviembre | O3: Diciembre | P3: Total | R3: %
C4: Mx ps. | D4: Budget 26 | E4: Budget 26 | F4: Budget 26 | G4: Budget 26 | H4: Budget 26 | I4: Budget 26 | J4: Budget 26 | K4: Budget 26 | L4: Budget 26 | M4: Budget 26 | N4: Budget 26 | O4: Budget 26 | P4: Budget 26 | R4: of Total
A6: CUENTA | B6: SUBCUENTA | C6: HEAD COUNT | D6: =$D$202 -> 30 | E6: =$D$202 -> 30 | F6: =$D$202 -> 30 | G6: =$D$202 -> 30 | H6: =$D$202 -> 30 | I6: =$D$202 -> 30 | J6: =$D$202 -> 30 | K6: =$D$202 -> 30 | ... O6: =$D$202 -> 30 | P6: =+O6 -> 30
C8: SUELDOS Y SALARIOS | D8: =+F202 -> 433608.61 | E8: =+D8 -> 433608.61 | F8: =+E8 -> 433608.61 | G8: =+$F$202 -> 433608.61 | H8: =+$F$202 -> 433608.61 | I8: =+$F$202 -> 433608.61 | J8: =+$F$202 -> 433608.61 | K8: =+$F$202 -> 433608.61 | L8: =+$F$202 -> 433608.61 | M8: =+$F$202 -> 433608.61 | N8: =+$F$202 -> 433608.61 | O8: =+$F$202 -> 433608.61 | P8: =+SUM(D8:O8) -> 5203303.3 | R8: =+IF(P8=0,0,P8/$P$159) -> 0.62780603
C9: Beneficios
C10: VALES DE DESPENSA | D10: =+$S$202 -> 0 | E10: =+$S$202 -> 0 | F10: =+$S$202 -> 0 | G10: =+$S$202*(IPC+1) -> 0 | H10: =+$S$202*(IPC+1) -> 0 | I10: =+$S$202*(IPC+1) -> 0 | J10: =+$S$202*(IPC+1) -> 0 | K10: =+$S$202*(IPC+1) -> 0 | L10: =+$S$202*(IPC+1) -> 0 | M10: =+$S$202*(IPC+1) -> 0 | N10: =+$S$202*(IPC+1) -> 0 | O10: =+$S$202*(IPC+1) -> 0 | P10: =+SUM(D10:O10) -> 0 | R10: =+IF(P10=0,0,P10/$P$159) -> 0
C11: AGUINALDO | D11: =+$O$202 -> 18067.025 | E11: =+$O$202 -> 18067.025 | F11: =+$O$202 -> 18067.025 | G11: =+$O$202*(IPC+1) -> 18731.892 | H11: =+$O$202*(IPC+1) -> 18731.892 | I11: =+$O$202*(IPC+1) -> 18731.892 | J11: =+$O$202*(IPC+1) -> 18731.892 | K11: =+$O$202*(IPC+1) -> 18731.892 | L11: =+$O$202*(IPC+1) -> 18731.892 | M11: =+$O$202*(IPC+1) -> 18731.892 | N11: =+$O$202*(IPC+1) -> 18731.892 | O11: =+$O$202*(IPC+1) -> 18731.892 | P11: =+SUM(D11:O11) -> 222788.1 | R11: =+IF(P11=0,0,P11/$P$159) -> 0.026880561
C12: BONOS | D12: 0 | E12: 0 | F12: 0 | G12: 0 | H12: 0 | I12: 0 | J12: 0 | K12: 0 | L12: 0 | M12: 0 | N12: 0 | O12: 0 | P12: =+SUM(D12:O12) -> 0 | R12: =+IF(P12=0,0,P12/$P$159) -> 0
C13: COMPENSACIONES | D13: =+$Q$202 -> 0 | E13: =+$Q$202 -> 0 | F13: =+$Q$202 -> 0 | G13: =+$Q$202*(IPC+1) -> 0 | H13: =+$Q$202*(IPC+1) -> 0 | I13: =+$Q$202*(IPC+1) -> 0 | J13: =+$Q$202*(IPC+1) -> 0 | K13: =+$Q$202*(IPC+1) -> 0 | L13: =+$Q$202*(IPC+1) -> 0 | M13: =+$Q$202*(IPC+1) -> 0 | N13: =+$Q$202*(IPC+1) -> 0 | O13: =+$Q$202*(IPC+1) -> 0 | P13: =+SUM(D13:O13) -> 0 | R13: =+IF(P13=0,0,P13/$P$159) -> 0
C14: DIAS FESTIVOS | D14: =+$L$202 -> 0 | E14: =+$L$202 -> 0 | F14: =+$L$202 -> 0 | G14: =+$L$202*(IPC+1) -> 0 | H14: =+$L$202*(IPC+1) -> 0 | I14: =+$L$202*(IPC+1) -> 0 | J14: =+$L$202*(IPC+1) -> 0 | K14: =+$L$202*(IPC+1) -> 0 | L14: =+$L$202*(IPC+1) -> 0 | M14: =+$L$202*(IPC+1) -> 0 | N14: =+$L$202*(IPC+1) -> 0 | O14: =+$L$202*(IPC+1) -> 0 | P14: =+SUM(D14:O14) -> 0 | R14: =+IF(P14=0,0,P14/$P$159) -> 0
C15: HORAS EXTRAS | D15: =+$I$202 -> 0 | E15: =+$I$202 -> 0 | F15: =+$I$202 -> 0 | G15: =+$I$202*(IPC+1) -> 0 | H15: =+$I$202*(IPC+1) -> 0 | I15: =+$I$202*(IPC+1) -> 0 | J15: =+$I$202*(IPC+1) -> 0 | K15: =+$I$202*(IPC+1) -> 0 | L15: =+$I$202*(IPC+1) -> 0 | M15: =+$I$202*(IPC+1) -> 0 | N15: =+$I$202*(IPC+1) -> 0 | O15: =+$I$202*(IPC+1) -> 0 | P15: =+SUM(D15:O15) -> 0 | R15: =+IF(P15=0,0,P15/$P$159) -> 0
C16: INDEMNIZACIONES (DESPIDO) | D16: 0 | E16: 0 | F16: 0 | G16: 0 | H16: 0 | I16: 0 | J16: 0 | K16: 0 | L16: 0 | M16: 0 | N16: 0 | O16: 0 | P16: =+SUM(D16:O16) -> 0 | R16: =+IF(P16=0,0,P16/$P$159) -> 0
C17: PRIMA DE ANTIGUEDAD | D17: 0 | E17: 0 | F17: 0 | G17: 0 | H17: 0 | I17: 0 | J17: 0 | K17: 0 | L17: 0 | M17: 0 | N17: 0 | O17: 0 | P17: =+SUM(D17:O17) -> 0 | R17: =+IF(P17=0,0,P17/$P$159) -> 0
C18: PRIMA DOMINICAL | D18: 0 | E18: 0 | F18: 0 | G18: 0 | H18: 0 | I18: 0 | J18: 0 | K18: 0 | L18: 0 | M18: 0 | N18: 0 | O18: 0 | P18: =+SUM(D18:O18) -> 0 | R18: =+IF(P18=0,0,P18/$P$159) -> 0
C19: PRIMA VACACIONAL | D19: =+$R$202 -> 4215.6383 | E19: =+$R$202 -> 4215.6383 | F19: =+$R$202 -> 4215.6383 | G19: =+$R$202 -> 4215.6383 | H19: =+$R$202 -> 4215.6383 | I19: =+$R$202 -> 4215.6383 | J19: =+$R$202 -> 4215.6383 | K19: =+$R$202 -> 4215.6383 | ... O19: =+$R$202 -> 4215.6383 | P19: =+SUM(D19:O19) -> 50587.66 | R19: =+IF(P19=0,0,P19/$P$159) -> 0.0061036683 | W19: =+O19*(IPC+1) -> 4370.7738
C20: PREMIO DE ASISTENCIA | D20: 0 | E20: 0 | F20: 0 | G20: 0 | H20: 0 | I20: 0 | J20: 0 | K20: 0 | L20: 0 | M20: 0 | N20: 0 | O20: 0 | P20: =+SUM(D20:O20) -> 0 | R20: =+IF(P20=0,0,P20/$P$159) -> 0
C21: PREMIO DE PUNTUALIDAD | D21: 0 | E21: 0 | F21: 0 | G21: 0 | H21: 0 | I21: 0 | J21: 0 | K21: 0 | L21: 0 | M21: 0 | N21: 0 | O21: 0 | P21: =+SUM(D21:O21) -> 0 | R21: =+IF(P21=0,0,P21/$P$159) -> 0
C22: VACACIONES | D22: =+$P$202 -> 0 | E22: =+$P$202 -> 0 | F22: =+$P$202 -> 0 | G22: =+$P$202 -> 0 | H22: =+$P$202 -> 0 | I22: =+$P$202 -> 0 | J22: =+$P$202 -> 0 | K22: =+$P$202 -> 0 | ... O22: =+$P$202 -> 0 | P22: =+SUM(D22:O22) -> 0 | R22: =+IF(P22=0,0,P22/$P$159) -> 0
C23: GRATIFICACIONES | D23: 0 | E23: 0 | F23: 0 | G23: 0 | H23: 0 | I23: 0 | J23: 0 | K23: 0 | L23: 0 | M23: 0 | N23: 0 | O23: 0 | P23: =+SUM(D23:O23) -> 0 | R23: =+IF(P23=0,0,P23/$P$159) -> 0
C24: HORAS EXTRAS TRIPLES | D24: =+$J$202 -> 0 | E24: =+$J$202 -> 0 | F24: =+$J$202 -> 0 | G24: =+$J$202*(IPC+1) -> 0 | H24: =+$J$202*(IPC+1) -> 0 | I24: =+$J$202*(IPC+1) -> 0 | J24: =+$J$202*(IPC+1) -> 0 | K24: =+$J$202*(IPC+1) -> 0 | L24: =+$J$202*(IPC+1) -> 0 | M24: =+$J$202*(IPC+1) -> 0 | N24: =+$J$202*(IPC+1) -> 0 | O24: =+$J$202*(IPC+1) -> 0 | P24: =+SUM(D24:O24) -> 0 | R24: =+IF(P24=0,0,P24/$P$159) -> 0
C25: FONDO DE AHORRO | D25: =+$M$202 -> 0 | E25: =+$M$202 -> 0 | F25: =+$M$202 -> 0 | G25: =+$M$202*(IPC+1) -> 0 | H25: =+$M$202*(IPC+1) -> 0 | I25: =+$M$202*(IPC+1) -> 0 | J25: =+$M$202*(IPC+1) -> 0 | K25: =+$M$202*(IPC+1) -> 0 | L25: =+$M$202*(IPC+1) -> 0 | M25: =+$M$202*(IPC+1) -> 0 | N25: =+$M$202*(IPC+1) -> 0 | O25: =+$M$202*(IPC+1) -> 0 | P25: =+SUM(D25:O25) -> 0 | R25: =+IF(P25=0,0,P25/$P$159) -> 0
C26: COMISIONES SOBRE VENTAS | D26: 0 | E26: 0 | F26: 0 | G26: 0 | H26: 0 | I26: 0 | J26: 0 | K26: 0 | L26: 0 | M26: 0 | N26: 0 | O26: 0 | P26: =+SUM(D26:O26) -> 0 | R26: =+IF(P26=0,0,P26/$P$159) -> 0
C27: DESCANSO LABORADO | D27: =+$K$202 -> 0 | E27: =+$K$202 -> 0 | F27: =+$K$202 -> 0 | G27: =+$K$202*(IPC+1) -> 0 | H27: =+$K$202*(IPC+1) -> 0 | I27: =+$K$202*(IPC+1) -> 0 | J27: =+$K$202*(IPC+1) -> 0 | K27: =+$K$202*(IPC+1) -> 0 | L27: =+$K$202*(IPC+1) -> 0 | M27: =+$K$202*(IPC+1) -> 0 | N27: =+$K$202*(IPC+1) -> 0 | O27: =+$K$202*(IPC+1) -> 0 | P27: =+SUM(D27:O27) -> 0 | R27: =+IF(P27=0,0,P27/$P$159) -> 0
C28: VALES RESTAURANTE | D28: =+$H$202 -> 0 | E28: =+$H$202 -> 0 | F28: =+$H$202 -> 0 | G28: =+$H$202*(IPC+1) -> 0 | H28: =+$H$202*(IPC+1) -> 0 | I28: =+$H$202*(IPC+1) -> 0 | J28: =+$H$202*(IPC+1) -> 0 | K28: =+$H$202*(IPC+1) -> 0 | L28: =+$H$202*(IPC+1) -> 0 | M28: =+$H$202*(IPC+1) -> 0 | N28: =+$H$202*(IPC+1) -> 0 | O28: =+$H$202*(IPC+1) -> 0 | P28: =+SUM(D28:O28) -> 0 | R28: =+IF(P28=0,0,P28/$P$159) -> 0
C29: INDEMNIZACIONES (RETIRO) | D29: 0 | E29: 0 | F29: 0 | G29: 0 | H29: 0 | I29: 0 | J29: 0 | K29: 0 | L29: 0 | M29: 0 | N29: 0 | O29: 0 | P29: =+SUM(D29:O29) -> 0
C30: BONO DE AUTO | D30: 0 | E30: 0 | F30: 0 | G30: 0 | H30: 0 | I30: 0 | J30: 0 | K30: 0 | L30: 0 | M30: 0 | N30: 0 | O30: 0 | P30: =+SUM(D30:O30) -> 0
C31: TOTAL BENEFICIOS | D31: =SUM(D8:D30)-D22 -> 455891.27 | E31: =SUM(E8:E30)-E22 -> 455891.27 | F31: =SUM(F8:F30)-F22 -> 455891.27 | G31: =SUM(G8:G30)-G22 -> 456556.14 | H31: =SUM(H8:H30)-H22 -> 456556.14 | I31: =SUM(I8:I30)-I22 -> 456556.14 | J31: =SUM(J8:J30)-J22 -> 456556.14 | K31: =SUM(K8:K30)-K22 -> 456556.14 | ... P31: =SUM(P8:P30)-P22 -> 5476679.1 | R31: =+IF(P31=0,0,P31/$P$159) -> 0.66079026
C33: Impuestos + Comisiones
C34: IMSS PATRONAL | D34: 0 | E34: 0 | F34: 0 | G34: 0 | H34: 0 | I34: 0 | J34: 0 | K34: 0 | L34: 0 | M34: 0 | N34: 0 | O34: 0 | P34: =+SUM(D34:O34) -> 0 | R34: =+IF(P34=0,0,P34/$P$159) -> 0
C35: APORTACIONES AL INFONAVIT | D35: 0 | E35: 0 | F35: 0 | G35: 0 | H35: 0 | I35: 0 | J35: 0 | K35: 0 | L35: 0 | M35: 0 | N35: 0 | O35: 0 | P35: =+SUM(D35:O35) -> 0 | R35: =+IF(P35=0,0,P35/$P$159) -> 0
C36: SAR | D36: 0 | E36: 0 | F36: 0 | G36: 0 | H36: 0 | I36: 0 | J36: 0 | K36: 0 | L36: 0 | M36: 0 | N36: 0 | O36: 0 | P36: =+SUM(D36:O36) -> 0 | R36: =+IF(P36=0,0,P36/$P$159) -> 0
C37: 5% INFONAVIT | D37: 0 | E37: 0 | F37: 0 | G37: 0 | H37: 0 | I37: 0 | J37: 0 | K37: 0 | L37: 0 | M37: 0 | N37: 0 | O37: 0 | P37: =+SUM(D37:O37) -> 0 | R37: =+IF(P37=0,0,P37/$P$159) -> 0
C38: RETIRO CESANTIA Y VEJEZ | D38: 0 | E38: 0 | F38: 0 | G38: 0 | H38: 0 | I38: 0 | J38: 0 | K38: 0 | L38: 0 | M38: 0 | N38: 0 | O38: 0 | P38: =+SUM(D38:O38) -> 0 | R38: =+IF(P38=0,0,P38/$P$159) -> 0
C39: DIFERENCIAS INFONAVIT | D39: 0 | E39: 0 | F39: 0 | G39: 0 | H39: 0 | I39: 0 | J39: 0 | K39: 0 | L39: 0 | M39: 0 | N39: 0 | O39: 0 | P39: =+SUM(D39:O39) -> 0 | R39: =+IF(P39=0,0,P39/$P$159) -> 0
C40: DIFERENCIAS I.M.S.S. | D40: 0 | E40: 0 | F40: 0 | G40: 0 | H40: 0 | I40: 0 | J40: 0 | K40: 0 | L40: 0 | M40: 0 | N40: 0 | O40: 0 | P40: =+SUM(D40:O40) -> 0 | R40: =+IF(P40=0,0,P40/$P$159) -> 0
C41: IVA | D41: 0 | E41: 0 | F41: 0 | G41: 0 | H41: 0 | I41: 0 | J41: 0 | K41: 0 | L41: 0 | M41: 0 | N41: 0 | O41: 0 | P41: =+SUM(D41:O41) -> 0 | R41: =+IF(P41=0,0,P41/$P$159) -> 0
C42: Comisión | D42: =+D31*0.05 -> 22794.564 | E42: =+E31*0.05 -> 22794.564 | F42: =+F31*0.05 -> 22794.564 | G42: =+G31*0.05 -> 22827.807 | H42: =+H31*0.05 -> 22827.807 | I42: =+I31*0.05 -> 22827.807 | J42: =+J31*0.05 -> 22827.807 | K42: =+K31*0.05 -> 22827.807 | ... O42: =+O31*0.05 -> 22827.807 | P42: =+SUM(D42:O42) -> 273833.95 | R42: =+IF(P42=0,0,P42/$P$159) -> 0.033039513
C43: TOTAL IMPUESTOS | D43: =SUM(D34:D42) -> 22794.564 | E43: =SUM(E34:E42) -> 22794.564 | F43: =SUM(F34:F42) -> 22794.564 | G43: =SUM(G34:G42) -> 22827.807 | H43: =SUM(H34:H42) -> 22827.807 | I43: =SUM(I34:I42) -> 22827.807 | J43: =SUM(J34:J42) -> 22827.807 | K43: =SUM(K34:K42) -> 22827.807 | ... P43: =SUM(P34:P42) -> 273833.95 | R43: =+IF(P43=0,0,P43/$P$159) -> 0.033039513
...

Sheet Gral
A1: Población | B1: Nombre (s) | C1: Primer Apellido | D1: Segundo Apellido | E1: Dirección | F1: Departamento | G1: Nombre de Puesto | H1: Salario Base Mensual Actual 2026 | I1: Aguinaldo | J1: Prima Vacacional | K1: Bono Variable Anual PMP Ejecutivos (Target 100%) Se paga 30 Mar 2027 Base Mensual | L1: Vacaciones | M1: Bono Variable Anual PMP CAA (Target) Se paga 30 Mar 2027 Base Mensual | N1: Incentivo Variable Trimestral Cobranza-Costo-Servicio Objetivo Budget 2026 (Base Mensual) | O1: Bono Variable Mensual | P1: Comision Ventas $Est | Q1: Prestacion Vehiculo | R1: Compensación Fija | S1: Compensación Variable | T1: Compensación Total Mensual | U1: Total Compensacion anual
A2: LT | B2: LUIS | C2: MENDOZA | D2: GARDUÑO | E2: COMERCIAL | F2: DIRECCION | G2: DIRECTOR COMERCIAL | H2: 70000 | I2: =+H2/2 -> 35000 | J2: 7000 | K2: =H2/12 -> 5833.3333 | L2: =+(H2/30)*12 -> 28000 | N2: 10000 | Q2: 10000 | R2: =H2+I2+Q2 -> 115000 | S2: =K2+M2+N2+O2+P2 -> 15833.333 | T2: =R2+S2 -> 130833.33 | U2: =T2*12 -> 1570000
A3: LT | B3: MARIO FRANCISCO | C3: MORFIN | D3: RODRIGUEZ | E3: OPERACIONES | F3: DIRECCION | G3: DIRECTOR OPERATIVO | H3: 70000 | I3: =+H3/2 -> 35000 | J3: 8166.6667 | K3: =H3/12 -> 5833.3333 | L3: =+(H3/30)*14 -> 32666.667 | N3: 10000 | Q3: 10000 | R3: =H3+I3+Q3 -> 115000 | S3: =K3+M3+N3+O3+P3 -> 15833.333 | T3: =R3+S3 -> 130833.33 | U3: =T3*12 -> 1570000
A4: LT | B4: ERNESTO | C4: VELAZQUEZ | D4: JIMENEZ | E4: DIRECCION | F4: DIRECCION | G4: DIRECCION GENERAL | H4: 80000 | I4: =+H4/2 -> 40000 | J4: 9333.3333 | K4: =H4/12 -> 6666.6667 | L4: =+(H4/30)*14 -> 37333.333 | N4: =40000000*0.02/12 -> 66666.667 | Q4: 18000 | R4: =H4+I4+Q4 -> 138000 | S4: =K4+M4+N4+O4+P4 -> 73333.333 | T4: =R4+S4 -> 211333.33 | U4: =T4*12 -> 2536000
A5: LT | B5: ERNESTO | C5: SANCHEZ | D5: PALLARES | E5: FINANZAS | F5: DIRECCION | G5: DIRECTOR FINANZAS | H5: 60000 | I5: =+H5/2 -> 30000 | J5: 7000 | K5: =H5/12 -> 5000 | L5: =+(H5/30)*14 -> 28000 | N5: 5000 | Q5: 5000 | R5: =H5+I5+Q5 -> 95000 | S5: =K5+M5+N5+O5+P5 -> 10000 | T5: =R5+S5 -> 105000 | U5: =T5*12 -> 1260000
A6: LT | B6: LAURA | C6: UGALDE | D6: PEÑALOZA | E6: RECURSOS HUMANOS | F6: DIRECCION | G6: DIRECTOR RECURSOS HUMANOS | H6: 60000 | I6: =+H6/2 -> 30000 | J6: 6000 | K6: =H6/12 -> 5000 | L6: =+(H6/30)*12 -> 24000 | N6: 10000 | Q6: 10000 | R6: =H6+I6+Q6 -> 100000 | S6: =K6+M6+N6+O6+P6 -> 15000 | T6: =R6+S6 -> 115000 | U6: =T6*12 -> 1380000
A7: LT | B7: DIEGO JOSUE | C7: MALAGON | D7: MORALES | E7: TECNICA | F7: DIRECCION | G7: DIRECTOR TECNICO | H7: 39500 | I7: =+H7/2 -> 19750 | J7: 7241.6667 | K7: =H7/12 -> 3291.6667 | L7: =+(H7/30)*22 -> 28966.667 | N7: 5000 | Q7: 5000 | R7: =H7+I7+Q7 -> 64250 | S7: =K7+M7+N7+O7+P7 -> 8291.6667 | T7: =R7+S7 -> 72541.667 | U7: =T7*12 -> 870500
H8: =SUM(H2:H7) -> 379500 | I8: =SUM(I2:I7) -> 189750 | J8: =SUM(J2:J7) -> 44741.667 | K8: =SUM(K2:K7) -> 31625 | L8: =SUM(L2:L7) -> 178966.67 | N8: =SUM(N2:N7) -> 106666.67
I9: =+I8/12 -> 15812.5 | J9: =+J8/12 -> 3728.4722 | N9: =+N8/3 -> 35555.556
H10: =+H8+I9+J9+K8+N9 -> 466221.53
G11: Coms 5% | H11: =+H10*1.05 -> 489532.6
G12: IVA 16% | H12: =+H11 -> 489532.6

Sheet Gtos Gral
C1: 46023 | D1: 46054 | E1: 46082 | F1: 46113 | G1: 46143 | H1: 46174 | I1: 46204 | J1: 46235 | K1: 46266 | L1: 46296 | M1: 46327 | N1: 46357 | O1: Subtotal
A2: LT | B2: Alim & Beb | C2: 3000 | F2: 3000 | G2: 3000 | I2: 3000 | L2: 3000 | O2: =SUM(C2:N2) -> 15000
B3: Otros | G3: 2000 | O3: =SUM(C3:N3) -> 2000
B4: Traslados | O4: =SUM(C4:N4) -> 0
B5: Gasolina | G5: 1000 | O5: =SUM(C5:N5) -> 1000
B6: Hospedaje | O6: =SUM(C6:N6) -> 0
A7: ACCIONISTAS | B7: Alim & Beb | C7: 4000 | F7: 4000 | I7: 4000 | L7: 4000 | O7: =SUM(C7:N7) -> 16000
B8: Otros | O8: =SUM(C8:N8) -> 0
B9: Traslados | O9: =SUM(C9:N9) -> 0
B10: Gasolina | O10: =SUM(C10:N10) -> 0
B11: Hospedaje | O11: =SUM(C11:N11) -> 0
A12: CONSEJO | B12: Alim & Beb | H12: 10000 | N12: 10000 | O12: =SUM(C12:N12) -> 20000
B13: Otros | H13: 10000 | N13: 10000 | O13: =SUM(C13:N13) -> 20000
B14: Traslados | O14: =SUM(C14:N14) -> 0
B15: Gasolina | O15: =SUM(C15:N15) -> 0
B16: Hospedaje | O16: =SUM(C16:N16) -> 0
A17: TOTAL/MES | C17: =SUM(C2:C16) -> 7000 | D17: =SUM(D2:D16) -> 0 | E17: =SUM(E2:E16) -> 0 | F17: =SUM(F2:F16) -> 7000 | G17: =SUM(G2:G16) -> 6000 | H17: =SUM(H2:H16) -> 20000 | I17: =SUM(I2:I16) -> 7000 | J17: =SUM(J2:J16) -> 0 | ... O17: =SUM(O2:O16) -> 74000

Sheet Finanzas
C1: PS PROCESO SEGURO, SC | D1: Centro de Costos: | E1: CC | F1: UNIDAD | V1: 0.0368 | W1: % DE INCREMENTO A PARTIR DE ENERO
D2: 0 | E2: =+D2+1 -> 1 | F2: =+E2+1 -> 2 | G2: =+F2+1 -> 3 | H2: =+G2+1 -> 4 | I2: =+H2+1 -> 5 | J2: =+I2+1 -> 6 | K2: =+J2+1 -> 7 | L2: =+K2+1 -> 8 | ... P2: =+O2+1 -> 12
C3: Budget 2026 Expenses | D3: Enero | E3: Febrero | F3: Marzo | G3: Abril | H3: Mayo | I3: Junio | J3: Julio | K3: Agosto | L3: Septiembre | M3: Octubre | N3: Noviembre | O3: Diciembre | P3: Total | R3: %
C4: Mx ps. | D4: Budget 26 | E4: Budget 26 | F4: Budget 26 | G4: Budget 26 | H4: Budget 26 | I4: Budget 26 | J4: Budget 26 | K4: Budget 26 | L4: Budget 26 | M4: Budget 26 | N4: Budget 26 | O4: Budget 26 | P4: Budget 26 | R4: of Total
A6: CUENTA | B6: SUBCUENTA | C6: HEAD COUNT | D6: =$D$180 -> 6 | E6: =$D$180 -> 6 | F6: =$D$180 -> 6 | G6: =$D$180 -> 6 | H6: =$D$180 -> 6 | I6: =$D$180 -> 6 | J6: =$D$180 -> 6 | K6: =$D$180 -> 6 | ... O6: =$D$180 -> 6 | P6: =+O6 -> 6
C8: SUELDOS Y SALARIOS | D8: 63902.4 | E8: =+D8 -> 63902.4 | F8: =+E8 -> 63902.4 | G8: =+$F$180 -> 87999.998 | H8: =+$F$180 -> 87999.998 | I8: =+$F$180 -> 87999.998 | J8: =+$F$180 -> 87999.998 | K8: =+$F$180 -> 87999.998 | L8: =+$F$180 -> 87999.998 | M8: =+$F$180 -> 87999.998 | N8: =+$F$180 -> 87999.998 | O8: =+$F$180 -> 87999.998 | P8: =+SUM(D8:O8) -> 983707.18 | R8: =+IF(P8=0,0,P8/$P$137) -> 0.44979357
C9: Beneficios
C10: VALES DE DESPENSA | D10: =+$S$180 -> 0 | E10: =+$S$180 -> 0 | F10: =+$S$180 -> 0 | G10: =+$S$180*(IPC+1) -> 0 | H10: =+$S$180*(IPC+1) -> 0 | I10: =+$S$180*(IPC+1) -> 0 | J10: =+$S$180*(IPC+1) -> 0 | K10: =+$S$180*(IPC+1) -> 0 | L10: =+$S$180*(IPC+1) -> 0 | M10: =+$S$180*(IPC+1) -> 0 | N10: =+$S$180*(IPC+1) -> 0 | O10: =+$S$180*(IPC+1) -> 0 | P10: =+SUM(D10:O10) -> 0 | R10: =+IF(P10=0,0,P10/$P$137) -> 0
C11: AGUINALDO | D11: 2662.6 | E11: 2662.6 | F11: 2662.6 | G11: =+$O$180 -> 3666.6666 | H11: =+$O$180 -> 3666.6666 | I11: =+$O$180 -> 3666.6666 | J11: =+$O$180 -> 3666.6666 | K11: =+$O$180 -> 3666.6666 | L11: =+$O$180 -> 3666.6666 | M11: =+$O$180 -> 3666.6666 | N11: =+$O$180 -> 3666.6666 | O11: =+$O$180 -> 3666.6666 | P11: =+SUM(D11:O11) -> 40987.799 | R11: =+IF(P11=0,0,P11/$P$137) -> 0.018741399
C12: CAA | D12: =+F146/12 -> 1750 | E12: =+D12 -> 1750 | F12: =+E12 -> 1750 | G12: =+F12 -> 1750 | H12: =+G12 -> 1750 | I12: =+H12 -> 1750 | J12: =+I12 -> 1750 | K12: =+J12 -> 1750 | L12: =+K12 -> 1750 | ... O12: =+N12 -> 1750 | P12: =+SUM(D12:O12) -> 21000 | R12: =+IF(P12=0,0,P12/$P$137) -> 0.0096021104
C13: COMPENSACIONES | D13: =+$Q$180 -> 0 | E13: =+$Q$180 -> 0 | F13: =+$Q$180 -> 0 | G13: =+$Q$180*(IPC+1) -> 0 | H13: =+$Q$180*(IPC+1) -> 0 | I13: =+$Q$180*(IPC+1) -> 0 | J13: =+$Q$180*(IPC+1) -> 0 | K13: =+$Q$180*(IPC+1) -> 0 | L13: =+$Q$180*(IPC+1) -> 0 | M13: =+$Q$180*(IPC+1) -> 0 | N13: =+$Q$180*(IPC+1) -> 0 | O13: =+$Q$180*(IPC+1) -> 0 | P13: =+SUM(D13:O13) -> 0 | R13: =+IF(P13=0,0,P13/$P$137) -> 0
C14: DIAS FESTIVOS | D14: =+$L$180 -> 0 | E14: =+$L$180 -> 0 | F14: =+$L$180 -> 0 | G14: =+$L$180*(IPC+1) -> 0 | H14: =+$L$180*(IPC+1) -> 0 | I14: =+$L$180*(IPC+1) -> 0 | J14: =+$L$180*(IPC+1) -> 0 | K14: =+$L$180*(IPC+1) -> 0 | L14: =+$L$180*(IPC+1) -> 0 | M14: =+$L$180*(IPC+1) -> 0 | N14: =+$L$180*(IPC+1) -> 0 | O14: =+$L$180*(IPC+1) -> 0 | P14: =+SUM(D14:O14) -> 0 | R14: =+IF(P14=0,0,P14/$P$137) -> 0
C15: HORAS EXTRAS | D15: =+$I$180 -> 0 | E15: =+$I$180 -> 0 | F15: =+$I$180 -> 0 | G15: =+$I$180*(IPC+1) -> 0 | H15: =+$I$180*(IPC+1) -> 0 | I15: =+$I$180*(IPC+1) -> 0 | J15: =+$I$180*(IPC+1) -> 0 | K15: =+$I$180*(IPC+1) -> 0 | L15: =+$I$180*(IPC+1) -> 0 | M15: =+$I$180*(IPC+1) -> 0 | N15: =+$I$180*(IPC+1) -> 0 | O15: =+$I$180*(IPC+1) -> 0 | P15: =+SUM(D15:O15) -> 0 | R15: =+IF(P15=0,0,P15/$P$137) -> 0
C16: INDEMNIZACIONES (DESPIDO) | D16: 0 | E16: 0 | F16: 0 | G16: 0 | H16: 0 | I16: 0 | J16: 0 | K16: 0 | L16: 0 | M16: 0 | N16: 0 | O16: 0 | P16: =+SUM(D16:O16) -> 0 | R16: =+IF(P16=0,0,P16/$P$137) -> 0
C17: PRIMA DE ANTIGUEDAD | D17: 0 | E17: 0 | F17: 0 | G17: 0 | H17: 0 | I17: 0 | J17: 0 | K17: 0 | L17: 0 | M17: 0 | N17: 0 | O17: 0 | P17: =+SUM(D17:O17) -> 0 | R17: =+IF(P17=0,0,P17/$P$137) -> 0
C18: PRIMA DOMINICAL | D18: 0 | E18: 0 | F18: 0 | G18: 0 | H18: 0 | I18: 0 | J18: 0 | K18: 0 | L18: 0 | M18: 0 | N18: 0 | O18: 0 | P18: =+SUM(D18:O18) -> 0 | R18: =+IF(P18=0,0,P18/$P$137) -> 0
C19: PRIMA VACACIONAL | D19: 574.18666 | E19: 574.18666 | F19: 574.18666 | G19: =+$R$180 -> 689.47221 | H19: =+$R$180 -> 689.47221 | I19: =+$R$180 -> 689.47221 | J19: =+$R$180 -> 689.47221 | K19: =+$R$180 -> 689.47221 | L19: =+$R$180 -> 689.47221 | M19: =+$R$180 -> 689.47221 | N19: =+$R$180 -> 689.47221 | O19: =+$R$180 -> 689.47221 | P19: =+SUM(D19:O19) -> 7927.8098 | R19: =+IF(P19=0,0,P19/$P$137) -> 0.0036249383 | W19: =+O19*(IPC+1) -> 714.84478
C20: PREMIO DE ASISTENCIA | D20: 0 | E20: 0 | F20: 0 | G20: 0 | H20: 0 | I20: 0 | J20: 0 | K20: 0 | L20: 0 | M20: 0 | N20: 0 | O20: 0 | P20: =+SUM(D20:O20) -> 0 | R20: =+IF(P20=0,0,P20/$P$137) -> 0
C21: PREMIO DE PUNTUALIDAD | D21: 0 | E21: 0 | F21: 0 | G21: 0 | H21: 0 | I21: 0 | J21: 0 | K21: 0 | L21: 0 | M21: 0 | N21: 0 | O21: 0 | P21: =+SUM(D21:O21) -> 0 | R21: =+IF(P21=0,0,P21/$P$137) -> 0
C22: VACACIONES | D22: 0 | E22: 0 | F22: 0 | G22: 0 | H22: =+$P$180 -> 0 | I22: =+$P$180 -> 0 | J22: =+$P$180 -> 0 | K22: =+$P$180 -> 0 | L22: =+$P$180 -> 0 | M22: =+$P$180 -> 0 | N22: =+$P$180 -> 0 | O22: =+$P$180 -> 0 | P22: =+SUM(D22:O22) -> 0 | R22: =+IF(P22=0,0,P22/$P$137) -> 0
C23: GRATIFICACIONES | D23: 0 | E23: 0 | F23: 0 | G23: 0 | H23: 0 | I23: 0 | J23: 0 | K23: 0 | L23: 0 | M23: 0 | N23: 0 | O23: 0 | P23: =+SUM(D23:O23) -> 0 | R23: =+IF(P23=0,0,P23/$P$137) -> 0
C24: HORAS EXTRAS TRIPLES | D24: =+$J$180 -> 0 | E24: =+$J$180 -> 0 | F24: =+$J$180 -> 0 | G24: =+$J$180*(IPC+1) -> 0 | H24: =+$J$180*(IPC+1) -> 0 | I24: =+$J$180*(IPC+1) -> 0 | J24: =+$J$180*(IPC+1) -> 0 | K24: =+$J$180*(IPC+1) -> 0 | L24: =+$J$180*(IPC+1) -> 0 | M24: =+$J$180*(IPC+1) -> 0 | N24: =+$J$180*(IPC+1) -> 0 | O24: =+$J$180*(IPC+1) -> 0 | P24: =+SUM(D24:O24) -> 0 | R24: =+IF(P24=0,0,P24/$P$137) -> 0
C25: FONDO DE AHORRO | D25: =+$M$180 -> 0 | E25: =+$M$180 -> 0 | F25: =+$M$180 -> 0 | G25: =+$M$180*(IPC+1) -> 0 | H25: =+$M$180*(IPC+1) -> 0 | I25: =+$M$180*(IPC+1) -> 0 | J25: =+$M$180*(IPC+1) -> 0 | K25: =+$M$180*(IPC+1) -> 0 | L25: =+$M$180*(IPC+1) -> 0 | M25: =+$M$180*(IPC+1) -> 0 | N25: =+$M$180*(IPC+1) -> 0 | O25: =+$M$180*(IPC+1) -> 0 | P25: =+SUM(D25:O25) -> 0 | R25: =+IF(P25=0,0,P25/$P$137) -> 0
C26: COMISIONES SOBRE VENTAS | D26: 0 | E26: 0 | F26: 0 | G26: 0 | H26: 0 | I26: 0 | J26: 0 | K26: 0 | L26: 0 | M26: 0 | N26: 0 | O26: 0 | P26: =+SUM(D26:O26) -> 0 | R26: =+IF(P26=0,0,P26/$P$137) -> 0
C27: DESCANSO LABORADO | D27: =+$K$180 -> 0 | E27: =+$K$180 -> 0 | F27: =+$K$180 -> 0 | G27: =+$K$180*(IPC+1) -> 0 | H27: =+$K$180*(IPC+1) -> 0 | I27: =+$K$180*(IPC+1) -> 0 | J27: =+$K$180*(IPC+1) -> 0 | K27: =+$K$180*(IPC+1) -> 0 | L27: =+$K$180*(IPC+1) -> 0 | M27: =+$K$180*(IPC+1) -> 0 | N27: =+$K$180*(IPC+1) -> 0 | O27: =+$K$180*(IPC+1) -> 0 | P27: =+SUM(D27:O27) -> 0 | R27: =+IF(P27=0,0,P27/$P$137) -> 0
C28: VALES RESTAURANTE | D28: =+$H$180 -> 0 | E28: =+$H$180 -> 0 | F28: =+$H$180 -> 0 | G28: =+$H$180*(IPC+1) -> 0 | H28: =+$H$180*(IPC+1) -> 0 | I28: =+$H$180*(IPC+1) -> 0 | J28: =+$H$180*(IPC+1) -> 0 | K28: =+$H$180*(IPC+1) -> 0 | L28: =+$H$180*(IPC+1) -> 0 | M28: =+$H$180*(IPC+1) -> 0 | N28: =+$H$180*(IPC+1) -> 0 | O28: =+$H$180*(IPC+1) -> 0 | P28: =+SUM(D28:O28) -> 0 | R28: =+IF(P28=0,0,P28/$P$137) -> 0
C29: INDEMNIZACIONES (RETIRO) | D29: 0 | E29: 0 | F29: 0 | G29: 0 | H29: 0 | I29: 0 | J29: 0 | K29: 0 | L29: 0 | M29: 0 | N29: 0 | O29: 0 | P29: =+SUM(D29:O29) -> 0
C30: BONO DE AUTO | D30: 0 | E30: 0 | F30: 0 | G30: 0 | H30: 0 | I30: 0 | J30: 0 | K30: 0 | L30: 0 | M30: 0 | N30: 0 | O30: 0 | P30: =+SUM(D30:O30) -> 0
C31: TOTAL BENEFICIOS | D31: =SUM(D8:D30)-D22 -> 68889.187 | E31: =SUM(E8:E30)-E22 -> 68889.187 | F31: =SUM(F8:F30)-F22 -> 68889.187 | G31: =SUM(G8:G30)-G22 -> 94106.137 | H31: =SUM(H8:H30)-H22 -> 94106.137 | I31: =SUM(I8:I30)-I22 -> 94106.137 | J31: =SUM(J8:J30)-J22 -> 94106.137 | K31: =SUM(K8:K30)-K22 -> 94106.137 | ... P31: =SUM(P8:P30)-P22 -> 1053622.8 | R31: =+IF(P31=0,0,P31/$P$137) -> 0.48176202
C33: Impuestos + Comisiones
C34: IMSS PATRONAL | D34: 0 | E34: 0 | F34: 0 | G34: 0 | H34: 0 | I34: 0 | J34: 0 | K34: 0 | L34: 0 | M34: 0 | N34: 0 | O34: 0 | P34: =+SUM(D34:O34) -> 0 | R34: =+IF(P34=0,0,P34/$P$137) -> 0
C35: APORTACIONES AL INFONAVIT | D35: 0 | E35: 0 | F35: 0 | G35: 0 | H35: 0 | I35: 0 | J35: 0 | K35: 0 | L35: 0 | M35: 0 | N35: 0 | O35: 0 | P35: =+SUM(D35:O35) -> 0 | R35: =+IF(P35=0,0,P35/$P$137) -> 0
C36: SAR | D36: 0 | E36: 0 | F36: 0 | G36: 0 | H36: 0 | I36: 0 | J36: 0 | K36: 0 | L36: 0 | M36: 0 | N36: 0 | O36: 0 | P36: =+SUM(D36:O36) -> 0 | R36: =+IF(P36=0,0,P36/$P$137) -> 0
C37: 5% INFONAVIT | D37: 0 | E37: 0 | F37: 0 | G37: 0 | H37: 0 | I37: 0 | J37: 0 | K37: 0 | L37: 0 | M37: 0 | N37: 0 | O37: 0 | P37: =+SUM(D37:O37) -> 0 | R37: =+IF(P37=0,0,P37/$P$137) -> 0
C38: RETIRO CESANTIA Y VEJEZ | D38: 0 | E38: 0 | F38: 0 | G38: 0 | H38: 0 | I38: 0 | J38: 0 | K38: 0 | L38: 0 | M38: 0 | N38: 0 | O38: 0 | P38: =+SUM(D38:O38) -> 0 | R38: =+IF(P38=0,0,P38/$P$137) -> 0
C39: DIFERENCIAS INFONAVIT | D39: 0 | E39: 0 | F39: 0 | G39: 0 | H39: 0 | I39: 0 | J39: 0 | K39: 0 | L39: 0 | M39: 0 | N39: 0 | O39: 0 | P39: =+SUM(D39:O39) -> 0 | R39: =+IF(P39=0,0,P39/$P$137) -> 0
C40: DIFERENCIAS I.M.S.S. | D40: 0 | E40: 0 | F40: 0 | G40: 0 | H40: 0 | I40: 0 | J40: 0 | K40: 0 | L40: 0 | M40: 0 | N40: 0 | O40: 0 | P40: =+SUM(D40:O40) -> 0 | R40: =+IF(P40=0,0,P40/$P$137) -> 0
C41: IVA | D41: =SUM(+D8+D42)*0.16 -> 10775.497 | E41: =SUM(+E8+E42)*0.16 -> 10775.497 | F41: =SUM(+F8+F42)*0.16 -> 10775.497 | G41: =SUM(+G8+G42)*0.16 -> 14832.849 | H41: =SUM(+H8+H42)*0.16 -> 14832.849 | I41: =SUM(+I8+I42)*0.16 -> 14832.849 | J41: =SUM(+J8+J42)*0.16 -> 14832.849 | K41: =SUM(+K8+K42)*0.16 -> 14832.849 | ... O41: =SUM(+O8+O42)*0.16 -> 14832.849 | P41: =+SUM(D41:O41) -> 165822.13 | R41: =+IF(P41=0,0,P41/$P$137) -> 0.075821067
C42: Comisión | D42: =+D31*0.05 -> 3444.4593 | E42: =+E31*0.05 -> 3444.4593 | F42: =+F31*0.05 -> 3444.4593 | G42: =+G31*0.05 -> 4705.3068 | H42: =+H31*0.05 -> 4705.3068 | I42: =+I31*0.05 -> 4705.3068 | J42: =+J31*0.05 -> 4705.3068 | K42: =+K31*0.05 -> 4705.3068 | ... O42: =+O31*0.05 -> 4705.3068 | P42: =+SUM(D42:O42) -> 52681.14 | R42: =+IF(P42=0,0,P42/$P$137) -> 0.024088101
C43: TOTAL IMPUESTOS | D43: =SUM(D34:D42) -> 14219.957 | E43: =SUM(E34:E42) -> 14219.957 | F43: =SUM(F34:F42) -> 14219.957 | G43: =SUM(G34:G42) -> 19538.156 | H43: =SUM(H34:H42) -> 19538.156 | I43: =SUM(I34:I42) -> 19538.156 | J43: =SUM(J34:J42) -> 19538.156 | K43: =SUM(K34:K42) -> 19538.156 | ... P43: =SUM(P34:P42) -> 218503.27 | R43: =+IF(P43=0,0,P43/$P$137) -> 0.099909168
...

Sheet Comercial
A1: Población | B1: Nombre (s) | C1: Primer Apellido | D1: Segundo Apellido | E1: Dirección | F1: Departamento | G1: Nombre de Puesto | H1: Salario Base Mensual Actual 2026 | I1: Aguinaldo | J1: Prima Vacacional | K1: Bono Variable Anual PMP Ejecutivos (Target 100%) Se paga 30 Mar 2027 Base Mensual | L1: Bono Variable Anual PMP CAA (Target) Se paga 30 Mar 2027 Base Mensual | M1: Incentivo Variable Trimestral Cobranza-Costo-Servicio Objetivo Budget 2026 (Base Mensual) | N1: Bono Variable Mensual | O1: Comision Ventas $Est | P1: Prestacion Vehiculo | Q1: Compensación Fija | R1: Compensación Variable | S1: Compensación Total Mensual | T1: Total Compensacion anual
A2: CAA | B2: EMMANUEL ALEJANDRO | C2: LOPEZ | D2: MORALES | E2: COMERCIAL | F2: VENTAS | G2: GERENTE SR DE VENTAS | H2: 28000 | I2: =+H2/2 -> 14000 | J2: =((H2/30)*14)*0.25 -> 3266.6667 | L2: =H2/12 -> 2333.3333 | O2: 46620.16 | Q2: =H2+I2+P2 -> 42000 | R2: =K2+L2+M2+N2+O2 -> 48953.493 | S2: =Q2+R2 -> 90953.493 | T2: =S2*12 -> 1091441.9
A3: CAA | B3: DANIELA | C3: GONZALEZ | D3: MARTOS | E3: COMERCIAL | F3: VENTAS | G3: GERENTE SR DE VENTAS | H3: 35000 | I3: =+H3/2 -> 17500 | J3: =((H3/30)*14)*0.25 -> 4083.3333 | L3: =H3/12 -> 2916.6667 | O3: 10000 | Q3: =H3+I3+P3 -> 52500 | R3: =K3+L3+M3+N3+O3 -> 12916.667 | S3: =Q3+R3 -> 65416.667 | T3: =S3*12 -> 785000
A4: CAA | B4: NAYELI DEL CARMEN | C4: RAMIREZ | D4: GONZALEZ | E4: COMERCIAL | F4: COMPRAS | G4: GERENTE SR COMPRAS | H4: 28000 | I4: =+H4/2 -> 14000 | J4: =((H4/30)*14)*0.25 -> 3266.6667 | L4: =H4/12 -> 2333.3333 | Q4: =H4+I4+P4 -> 42000 | R4: =K4+L4+M4+N4+O4 -> 2333.3333 | S4: =Q4+R4 -> 44333.333 | T4: =S4*12 -> 532000
A5: CAA | B5: NATALIA | C5: BRAVO | D5: ZAPIAIN | E5: COMERCIAL | F5: VENTAS | G5: JEFATURA DE ADMINISTRACION DE VENTAS | H5: 18000 | I5: =+H5/2 -> 9000 | J5: =((H5/30)*14)*0.25 -> 2100 | L5: =H5/12 -> 1500 | O5: 8243.85 | Q5: =H5+I5+P5 -> 27000 | R5: =K5+L5+M5+N5+O5 -> 9743.85 | S5: =Q5+R5 -> 36743.85 | T5: =S5*12 -> 440926.2
B6: AMERICA GUADALUPE | C6: MARTINEZ | D6: RANGEL | E6: COMERCIAL | F6: VENTAS | G6: ASESOR COMERCIAL | H6: 15000 | I6: =+H6/2 -> 7500 | J6: =((H6/30)*14)*0.25 -> 1750 | O6: 15848.57 | Q6: =H6+I6+P6 -> 22500 | R6: =K6+L6+M6+N6+O6 -> 15848.57 | S6: =Q6+R6 -> 38348.57 | T6: =S6*12 -> 460182.84
B7: DAVID ALEJANDRO | C7: MUI | D7: DAZA | E7: COMERCIAL | F7: VENTAS | G7: ASESOR COMERCIAL | H7: 15000 | I7: =+H7/2 -> 7500 | J7: =((H7/30)*14)*0.25 -> 1750 | O7: 14824.33 | Q7: =H7+I7+P7 -> 22500 | R7: =K7+L7+M7+N7+O7 -> 14824.33 | S7: =Q7+R7 -> 37324.33 | T7: =S7*12 -> 447891.96
B8: MOISES | C8: RIVERA | D8: CERON | E8: COMERCIAL | F8: VENTAS | G8: ASESOR COMERCIAL | H8: 15000 | I8: =+H8/2 -> 7500 | J8: =((H8/30)*14)*0.25 -> 1750 | O8: 13423.56 | Q8: =H8+I8+P8 -> 22500 | R8: =K8+L8+M8+N8+O8 -> 13423.56 | S8: =Q8+R8 -> 35923.56 | T8: =S8*12 -> 431082.72
B9: VICTOR MANUEL | C9: ALVAREZ | D9: CHAVEZ | E9: COMERCIAL | F9: VENTAS | G9: ASESOR COMERCIAL | H9: 15000 | I9: =+H9/2 -> 7500 | J9: =((H9/30)*14)*0.25 -> 1750 | O9: 13282.56 | Q9: =H9+I9+P9 -> 22500 | R9: =K9+L9+M9+N9+O9 -> 13282.56 | S9: =Q9+R9 -> 35782.56 | T9: =S9*12 -> 429390.72
B10: CLEIVER JOSE | C10: FERNANDEZ | D10: PEREZ | E10: COMERCIAL | F10: VENTAS | G10: ASESOR COMERCIAL | H10: 14000 | I10: =+H10/2 -> 7000 | J10: =((H10/30)*14)*0.25 -> 1633.3333 | O10: 5858.23 | Q10: =H10+I10+P10 -> 21000 | R10: =K10+L10+M10+N10+O10 -> 5858.23 | S10: =Q10+R10 -> 26858.23 | T10: =S10*12 -> 322298.76
B11: FREDDY JESUS | C11: ALMANZA | D11: GUZMAN | E11: COMERCIAL | F11: DISEÑO | G11: DISEÑADOR SR | H11: 19000 | I11: =+H11/2 -> 9500 | J11: =((H11/30)*14)*0.25 -> 2216.6667 | Q11: =H11+I11+P11 -> 28500 | R11: =K11+L11+M11+N11+O11 -> 0 | S11: =Q11+R11 -> 28500 | T11: =S11*12 -> 342000
B12: CIRO ALBERTO | C12: HERNANDEZ | D12: AGUILAR | E12: COMERCIAL | F12: COMPRAS | G12: COMPRADOR | H12: 16000 | I12: =+H12/2 -> 8000 | J12: =((H12/30)*14)*0.25 -> 1866.6667 | Q12: =H12+I12+P12 -> 24000 | R12: =K12+L12+M12+N12+O12 -> 0 | S12: =Q12+R12 -> 24000 | T12: =S12*12 -> 288000
B13: BIANCA FRANCISCA | C13: DE LA VEGA | D13: ALCALA | E13: COMERCIAL | F13: COMPRAS | G13: COMPRADOR | H13: 16000 | I13: =+H13/2 -> 8000 | J13: =((H13/30)*14)*0.25 -> 1866.6667 | Q13: =H13+I13+P13 -> 24000 | R13: =K13+L13+M13+N13+O13 -> 0 | S13: =Q13+R13 -> 24000 | T13: =S13*12 -> 288000
B14: MIGUEL ANGEL | C14: AREVALO | D14: CERVANTES | E14: COMERCIAL | F14: DISEÑO | G14: DISEÑADOR SR | H14: 16000 | I14: =+H14/2 -> 8000 | J14: =((H14/30)*14)*0.25 -> 1866.6667 | Q14: =H14+I14+P14 -> 24000 | R14: =K14+L14+M14+N14+O14 -> 0 | S14: =Q14+R14 -> 24000 | T14: =S14*12 -> 288000
B15: MARIA FERNANDA | C15: FRANCO | D15: AGUILAR | E15: COMERCIAL | F15: VENTAS | G15: ADMINISTRADOR DE VENTAS JR | H15: 12000 | I15: =+H15/2 -> 6000 | J15: =((H15/30)*14)*0.25 -> 1400 | Q15: =H15+I15+P15 -> 18000 | R15: =K15+L15+M15+N15+O15 -> 0 | S15: =Q15+R15 -> 18000 | T15: =S15*12 -> 216000
B16: GERARDO DANIEL | C16: PALETA | D16: CALDERON | E16: COMERCIAL | F16: DISEÑO | G16: DISEÑADOR JR | H16: 11000 | I16: =+H16/2 -> 5500 | J16: =((H16/30)*14)*0.25 -> 1283.3333 | Q16: =H16+I16+P16 -> 16500 | R16: =K16+L16+M16+N16+O16 -> 0 | S16: =Q16+R16 -> 16500 | T16: =S16*12 -> 198000
B17: ARTURO | C17: CABRERA | D17: TERAN | E17: COMERCIAL | F17: DISEÑO | G17: ARTISTA VISUAL 3D | H17: 10500 | I17: =+H17/2 -> 5250 | J17: =((H17/30)*14)*0.25 -> 1225 | Q17: =H17+I17+P17 -> 15750 | R17: =K17+L17+M17+N17+O17 -> 0 | S17: =Q17+R17 -> 15750 | T17: =S17*12 -> 189000
B18: NUR | C18: MENDOZA | D18: ALARCON | E18: COMERCIAL | F18: DISEÑO | G18: PRACTICANTE DE DISEÑO JR | H18: 7000 | I18: =+H18/2 -> 3500 | J18: =((H18/30)*14)*0.25 -> 816.66667 | Q18: =H18+I18+P18 -> 10500 | R18: =K18+L18+M18+N18+O18 -> 0 | S18: =Q18+R18 -> 10500 | T18: =S18*12 -> 126000
H19: =SUM(H2:H18) -> 290500 | I19: =SUM(I2:I18)/12 -> 12104.167 | J19: =SUM(J2:J18)/12 -> 2824.3056 | L19: =SUM(L2:L18) -> 9083.3333 | O19: =SUM(O2:O18) -> 128101.26
H20: =+H19+I19+J19+O19+L19 -> 442613.07
H21: =+H20*1.05 -> 464743.72
H22: =+H21*1.16 -> 539102.71

Sheet Gtos Com
A1: Equipo | B1: Cliente | C1: Lugar | D1: Fecha prob | E1: dias | F1: hospedaje | G1: transporte | H1: uber | I1: alimentos | J1: otros | K1: Total
A2: Ame | B2: Scotiabank | C2: CDMX | D2: Febrero | E2: 1 | F2: 0 | G2: 1500 | H2: 0 | I2: 1500 | J2: 0 | K2: =SUM(F2:J2) -> 3000
A3: Alex | B3: Pepsico | C3: Chiapas | D3: Marzo | E3: 4 | F3: =E3*1400 -> 5600 | G3: 5000 | H3: 2500 | I3: =250*8 -> 2000 | J3: 0 | K3: =SUM(F3:J3) -> 15100
A4: Moises | B4: Adidas | C4: cdmx | D4: marzo | E4: 1 | F4: 0 | G4: 1500 | H4: 0 | I4: 1500 | J4: 0 | K4: =SUM(F4:J4) -> 3000
A5: Moises | B5: FRAGUA | C5: guadalajara | D5: marzo | E5: 2 | F5: =1400*2 -> 2800 | G5: 2000 | H5: 0 | I5: 1500 | J5: 0 | K5: =SUM(F5:J5) -> 6300
A6: Moises | B6: Charly | C6: Leon | D6: marzo | E6: 1 | F6: 0 | G6: 2000 | H6: 0 | I6: 1500 | J6: 0 | K6: =SUM(F6:J6) -> 3500
A7: Vic | B7: total play | C7: CDMX | D7: marzo | E7: 1 | F7: 0 | G7: 1500 | H7: 0 | I7: 1500 | J7: 0 | K7: =SUM(F7:J7) -> 3000
A8: Ame | B8: Scotiabank | C8: CDMX | D8: Marzo | E8: 1 | F8: 0 | G8: 1500 | H8: 0 | I8: 1500 | J8: 0 | K8: =SUM(F8:J8) -> 3000
A9: Ame | B9: Scotiabank | C9: CDMX | D9: marzo | E9: 1 | F9: 0 | G9: 1500 | H9: 0 | I9: 1500 | J9: 0 | K9: =SUM(F9:J9) -> 3000
A10: Ame | B10: Scotiabank | C10: CDMX | D10: marzo | E10: 1 | F10: 0 | G10: 1500 | H10: 0 | I10: 1500 | J10: 0 | K10: =SUM(F10:J10) -> 3000
A11: David | B11: DHL | C11: CDMX | D11: Marzo | E11: 1 | F11: 0 | G11: 1500 | H11: 0 | I11: 1500 | J11: 0 | K11: =SUM(F11:J11) -> 3000
A12: David | B12: DHL | C12: CDMX | D12: marzo | E12: 1 | F12: 0 | G12: 1500 | H12: 0 | I12: 1500 | J12: 0 | K12: =SUM(F12:J12) -> 3000
A13: David | B13: DHL | C13: CDMX | D13: marzo | E13: 1 | F13: 0 | G13: 1500 | H13: 0 | I13: 1500 | J13: 0 | K13: =SUM(F13:J13) -> 3000
A14: NAT | B14: Marsh | C14: CDMX | D14: marzo | E14: 1 | F14: 0 | G14: 1500 | H14: 0 | I14: 1500 | J14: 0 | K14: =SUM(F14:J14) -> 3000
A15: Vic | B15: solistica | C15: CDMX | D15: abril | E15: 1 | F15: 0 | G15: 1500 | H15: 0 | I15: 1500 | J15: 0 | K15: =SUM(F15:J15) -> 3000
A16: Ame | B16: Scotiabank | C16: CDMX | D16: abril | E16: 1 | F16: 0 | G16: 1500 | H16: 0 | I16: 1500 | J16: 0 | K16: =SUM(F16:J16) -> 3000
A17: David | B17: DHL | C17: CDMX | D17: abril | E17: 1 | F17: 0 | G17: 1500 | H17: 0 | I17: 1500 | J17: 0 | K17: =SUM(F17:J17) -> 3000
... A19: Cleiver | B19: Elektra | C19: CDMX | D19: abril | E19: 1 | F19: 0 | G19: 1500 | H19: 0 | I19: 1500 | J19: 0 | K19: =SUM(F19:J19) -> 3000
A20: Alex | B20: Pepsico | C20: merida | D20: mayo | E20: 4 | F20: =E20*1400 -> 5600 | G20: 5000 | H20: 2500 | I20: =250*8 -> 2000 | J20: 0 | K20: =SUM(F20:J20) -> 15100
A21: Vic | B21: RIVALIA | C21: CDMX | D21: mayo | E21: 1 | F21: 0 | G21: 1500 | H21: 0 | I21: 1500 | J21: 0 | K21: =SUM(F21:J21) -> 3000
A22: Ame | B22: izzi | C22: CDMX | D22: mayo | E22: 1 | F22: 0 | G22: 1500 | H22: 0 | I22: 1500 | J22: 0 | K22: =SUM(F22:J22) -> 3000
A23: NAT | B23: FEDEX | C23: CDMX | D23: mayo | E23: 1 | F23: 0 | G23: 1500 | H23: 0 | I23: 1500 | J23: 0 | K23: =SUM(F23:J23) -> 3000
A24: Cleiver | B24: Elektra | C24: CDMX | D24: mayo | E24: 1 | F24: 0 | G24: 1500 | H24: 0 | I24: 1500 | J24: 0 | K24: =SUM(F24:J24) -> 3000
A25: Cleiver | B25: Elektra | C25: edo mex | D25: mayo | E25: 1 | F25: 0 | G25: 1500 | H25: 0 | I25: 1500 | J25: 0 | K25: =SUM(F25:J25) -> 3000
A26: Moises | B26: FRAGUA | C26: guadalajara | D26: junio | E26: 2 | F26: =1400*2 -> 2800 | G26: 2000 | H26: 0 | I26: 1500 | J26: 0 | K26: =SUM(F26:J26) -> 6300
A27: Cleiver | B27: Elektra | C27: CDMX | D27: junio | E27: 1 | F27: 0 | G27: 1500 | H27: 0 | I27: 1500 | J27: 0 | K27: =SUM(F27:J27) -> 3000
A28: Cleiver | B28: Elektra | C28: edo mex | D28: junio | E28: 1 | F28: 0 | G28: 1500 | H28: 0 | I28: 1500 | J28: 0 | K28: =SUM(F28:J28) -> 3000
A29: Alex | B29: Pepsico | C29: mexicali | D29: julio | E29: 3 | F29: =E29*1400 -> 4200 | G29: 5000 | H29: 2500 | I29: =250*8 -> 2000 | J29: 0 | K29: =SUM(F29:J29) -> 13700
