Workbook

Sheet Sheet1
A1: CATEGORIA_NETSUITE | B1: Concepto | C1: IS | D1: ÁREA | E1: ZONA PPTO | F1: EMPLEADO | G1: MONTO | H1: PERIODO | I1: AREA | J1: ZONA | K1: PCT_POND | L1: Fecha | M1: Tipo | N1: Número | O1: Clasf Efs | P1: ID SGN | Q1: PUESTO | R1: PAGADORA
A2: Sueldos y salarios | B2: ACEVEDO LOPEZ GERMAIN | C2: COGS | D2: OPERACIONES | E2: CENTRO | F2: GERMAIN ACEVEDO LOPEZ | G2: 12269.305 | H2: ENERO
A3: Sueldos y salarios | B3: ACEVEDO LOPEZ GERMAIN | C3: COGS | D3: OPERACIONES | E3: CENTRO | F3: GERMAIN ACEVEDO LOPEZ | G3: 12620.03 | H3: MARZO
A4: Sueldos y salarios | B4: ACEVEDO LOPEZ GERMAIN | C4: COGS | D4: OPERACIONES | E4: CENTRO | F4: GERMAIN ACEVEDO LOPEZ | G4: 10861.391 | H4: FEBRERO
A5: Sueldos y salarios | B5: ACEVEDO LOPEZ GERMAIN | C5: COGS | D5: OPERACIONES | E5: CENTRO | F5: GERMAIN ACEVEDO LOPEZ | G5: 10842.303 | H5: ABRIL
A6: Sueldos y salarios | B6: AGUILAR MORALES EMANUEL | C6: COGS | D6: OPERACIONES | E6: CENTRO | F6: EMANUEL AGUILAR MORALES | G6: 24075.35 | H6: MARZO
A7: Sueldos y salarios | B7: AGUILAR MORALES EMANUEL | C7: COGS | D7: OPERACIONES | E7: CENTRO | F7: EMANUEL AGUILAR MORALES | G7: 14312.507 | H7: FEBRERO
A8: Sueldos y salarios | B8: ALCANTARA SEGURA MIRIAM JOSEFINA | C8: GASTOS DE ADMINISTRACIÓN | D8: TÉCNICO | F8: MIRIAM JOSEFINA ALCANTARA SEGURA | G8: 14378.848 | H8: ENERO
A9: Sueldos y salarios | B9: ALCANTARA SEGURA MIRIAM JOSEFINA | C9: GASTOS DE ADMINISTRACIÓN | D9: TÉCNICO | F9: MIRIAM JOSEFINA ALCANTARA SEGURA | G9: 15993.283 | H9: MARZO
A10: Sueldos y salarios | B10: ALCANTARA SEGURA MIRIAM JOSEFINA | C10: GASTOS DE ADMINISTRACIÓN | D10: TÉCNICO | F10: MIRIAM JOSEFINA ALCANTARA SEGURA | G10: 15770.154 | H10: FEBRERO
A11: Sueldos y salarios | B11: ALMADA NOZATO DANNA PAOLA | C11: COGS | D11: OPERACIONES | E11: SURESTE | F11: DANNA PAOLA ALMADA NOZATO | G11: 13779.069 | H11: MARZO
A12: Sueldos y salarios | B12: ALMADA NOZATO DANNA PAOLA | C12: COGS | D12: OPERACIONES | E12: SURESTE | F12: DANNA PAOLA ALMADA NOZATO | G12: 13493.097 | H12: FEBRERO
A13: Sueldos y salarios | B13: ALMADA NOZATO DANNA PAOLA | C13: COGS | D13: OPERACIONES | E13: SURESTE | F13: DANNA PAOLA ALMADA NOZATO | G13: 13751.394 | H13: ENERO
A14: Sueldos y salarios | B14: ALMANZA GUZMAN FREDDY JESUS | C14: GASTOS DE ADMINISTRACIÓN | D14: BRAND BUILDING | F14: FREDDY JESUS ALMANZA GUZMAN | G14: 19234.553 | H14: ENERO
A15: Sueldos y salarios | B15: ALMANZA GUZMAN FREDDY JESUS | C15: GASTOS DE ADMINISTRACIÓN | D15: BRAND BUILDING | F15: FREDDY JESUS ALMANZA GUZMAN | G15: 23356.679 | H15: MARZO
A16: Sueldos y salarios | B16: ALMANZA GUZMAN FREDDY JESUS | C16: GASTOS DE ADMINISTRACIÓN | D16: BRAND BUILDING | F16: FREDDY JESUS ALMANZA GUZMAN | G16: 18896.204 | H16: FEBRERO
A17: Sueldos y salarios | B17: ALTAMIRANO DIAZ CIELO ANEL | C17: COGS | D17: OPERACIONES | E17: NOROESTE | F17: CIELO ANEL ALTAMIRANO DIAZ | G17: 11487.986 | H17: MARZO
A18: Sueldos y salarios | B18: ALTAMIRANO DIAZ CIELO ANEL | C18: COGS | D18: OPERACIONES | E18: NOROESTE | F18: CIELO ANEL ALTAMIRANO DIAZ | G18: 17785.736 | H18: FEBRERO
A19: Sueldos y salarios | B19: ALTAMIRANO DIAZ CIELO ANEL | C19: COGS | D19: OPERACIONES | E19: NOROESTE | F19: CIELO ANEL ALTAMIRANO DIAZ | G19: 18125.363 | H19: ENERO
A20: Sueldos y salarios | B20: ALVAREZ CABRERA RODRIGO | C20: COGS | D20: OPERACIONES | E20: OCCIDENTE | F20: RODRIGO ALVAREZ CABRERA | G20: 19431.204 | H20: FEBRERO
A21: Sueldos y salarios | B21: ALVAREZ CABRERA RODRIGO | C21: COGS | D21: OPERACIONES | E21: OCCIDENTE | F21: RODRIGO ALVAREZ CABRERA | G21: 19779.553 | H21: ENERO
A22: Sueldos y salarios | B22: ALVAREZ CABRERA RODRIGO | C22: COGS | D22: OPERACIONES | E22: OCCIDENTE | F22: RODRIGO ALVAREZ CABRERA | G22: 15802.44 | H22: MARZO
A23: Sueldos y salarios | B23: ALVAREZ CABRERA RODRIGO | C23: COGS | D23: OPERACIONES | E23: OCCIDENTE | F23: RODRIGO ALVAREZ CABRERA | G23: 10060.44 | H23: ABRIL
A24: Sueldos y salarios | B24: ALVAREZ CHAVEZ VICTOR MANUEL | C24: GASTOS DE ADMINISTRACIÓN | D24: COMERCIAL | F24: VICTOR MANUEL ALVAREZ CHAVEZ | G24: 18848.226 | H24: FEBRERO
A25: Sueldos y salarios | B25: ALVAREZ CHAVEZ VICTOR MANUEL | C25: GASTOS DE ADMINISTRACIÓN | D25: COMERCIAL | F25: VICTOR MANUEL ALVAREZ CHAVEZ | G25: 19080.558 | H25: MARZO
A26: Sueldos y salarios | B26: ALVAREZ CHAVEZ VICTOR MANUEL | C26: GASTOS DE ADMINISTRACIÓN | D26: COMERCIAL | F26: VICTOR MANUEL ALVAREZ CHAVEZ | G26: 19207.063 | H26: ENERO
A27: Sueldos y salarios | B27: AREVALO CERVANTES MIGUEL ANGEL | C27: GASTOS DE ADMINISTRACIÓN | D27: BRAND BUILDING | F27: MIGUEL ANGEL AREVALO CERVANTES | G27: 20193.283 | H27: MARZO
A28: Sueldos y salarios | B28: AREVALO CERVANTES MIGUEL ANGEL | C28: GASTOS DE ADMINISTRACIÓN | D28: BRAND BUILDING | F28: MIGUEL ANGEL AREVALO CERVANTES | G28: 20050.154 | H28: FEBRERO
A29: Sueldos y salarios | B29: AREVALO CERVANTES MIGUEL ANGEL | C29: GASTOS DE ADMINISTRACIÓN | D29: BRAND BUILDING | F29: MIGUEL ANGEL AREVALO CERVANTES | G29: 20427.175 | H29: ENERO
A30: Sueldos y salarios | B30: ARRAZOLA SANTAELLA ALBERTO NICOLAS | C30: COGS | D30: OPERACIONES | E30: SURESTE | F30: ALBERTO NICOLAS ARRAZOLA SANTAELLA | G30: 8107.3609 | H30: FEBRERO
A31: Sueldos y salarios | B31: ARRAZOLA SANTAELLA ALBERTO NICOLAS | C31: COGS | D31: OPERACIONES | E31: SURESTE | F31: ALBERTO NICOLAS ARRAZOLA SANTAELLA | G31: 20303.011 | H31: MARZO
A32: Sueldos y salarios | B32: ARRAZOLA SANTAELLA ALBERTO NICOLAS | C32: COGS | D32: OPERACIONES | E32: SURESTE | F32: ALBERTO NICOLAS ARRAZOLA SANTAELLA | G32: 18427.44 | H32: ABRIL
A33: Sueldos y salarios | B33: ARREOLA ALATRISTE ALEXANDRA ESTEPHANIA | C33: COGS | D33: TÉCNICO | F33: ALEXANDRA ESTEPHANIA ARREOLA ALATRISTE | G33: 13202.829 | H33: MARZO
A34: Sueldos y salarios | B34: ARREOLA ALATRISTE ALEXANDRA ESTEPHANIA | C34: COGS | D34: TÉCNICO | F34: ALEXANDRA ESTEPHANIA ARREOLA ALATRISTE | G34: 10059.743 | H34: FEBRERO
A35: Sueldos y salarios | B35: ARREOLA ALATRISTE ALEXANDRA ESTEPHANIA | C35: COGS | D35: TÉCNICO | F35: ALEXANDRA ESTEPHANIA ARREOLA ALATRISTE | G35: 7350 | H35: ENERO
A36: Sueldos y salarios | B36: ARVIZU ESTRADA ALBA MARIANA | C36: COGS | D36: OPERACIONES | E36: CENTRO | F36: ALBA MARIANA ARVIZU ESTRADA | G36: 15770.03 | H36: MARZO
A37: Sueldos y salarios | B37: ARVIZU ESTRADA ALBA MARIANA | C37: COGS | D37: OPERACIONES | E37: CENTRO | F37: ALBA MARIANA ARVIZU ESTRADA | G37: 14071.391 | H37: FEBRERO
A38: Sueldos y salarios | B38: ARVIZU ESTRADA ALBA MARIANA | C38: COGS | D38: OPERACIONES | E38: CENTRO | F38: ALBA MARIANA ARVIZU ESTRADA | G38: 3209.1708 | H38: ENERO
A39: Sueldos y salarios | B39: ARVIZU ESTRADA ALBA MARIANA | C39: COGS | D39: OPERACIONES | E39: CENTRO | F39: ALBA MARIANA ARVIZU ESTRADA | G39: 15277.44 | H39: ABRIL
A40: Sueldos y salarios | B40: BACA AGUIRRE ANTONIO | C40: COGS | D40: OPERACIONES | E40: NOROESTE | F40: ANTONIO BACA AGUIRRE | G40: 17823.58 | H40: FEBRERO
...

Sheet 2025
A1: CATEGORIA_NETSUITE | B1: Concepto | C1: IS | D1: ÁREA | E1: ZONA PPTO | F1: EMPLEADO | G1: MONTO | H1: PERIODO | I1: NOTAS
A2: Viaticos y gastos de viaje | B2: COMPRA ORDEN DE PAGO SPEI 020125 =REFERENCIA CTA/CLABE: 002180650607646915, BXI SPEI BCO:002 BENEF:UBR PAGOS MEXICO SA DE CV (DATO NO VERIFICADO POR ESTA INSTITUCIÓN), Pago factura FFY 4293285 CVE RASTREO: 7875APR2202501023678059828 RFC: No capturado IVA: 000000000000.00 BANAMEX HORA LIQ: 10:51:50 | G2: $102,507.13 | H2: 45658 | I2: UBER
A3: Comisiones bancarias | B3: COMISION ORDEN DE PAGO SPEI REFERENCIA: 020125 | G3: $5.00 | H3: 45658 | I3: COMISIONES BANCARIAS
A4: Comisiones bancarias | B4: I.V.A. ORDEN DE PAGO SPEI REFERENCIA: 020125 | G4: $0.80 | H4: 45658 | I4: COMISIONES BANCARIAS
A5: Papeleria y articulos de oficina | B5: COMPRA ORDEN DE PAGO SPEI 020125 =REFERENCIA CTA/CLABE: 021320040177324969, BXI SPEI BCO:021 BENEF:ZAPOPAN ESCOLAR SA DE CV (DATO NO VERIFICADO POR ESTA INSTITUCIÓN), Pago factura ZES000225777 CVE RASTREO: 7875APR2202501023679087530 RFC: No capturado IVA: 000000000000.00 HSBC HORA LIQ: 15:42:26 | G5: $1,693.38 | H5: 45658 | I5: PAPELERIA
A6: Comisiones bancarias | B6: COMISION ORDEN DE PAGO SPEI REFERENCIA: 020125 | G6: $5.00 | H6: 45658 | I6: COMISIONES BANCARIAS
A7: Comisiones bancarias | B7: I.V.A. ORDEN DE PAGO SPEI REFERENCIA: 020125 | G7: $0.80 | H7: 45658 | I7: COMISIONES BANCARIAS
A8: Arrendamiento Automotriz | B8: 0229984CARGO DOMICILIACION CGO DOMICILIACION:VW Leasing LEYENDA: VOLKSWAGEN LEASING REF SERV EMISOR:0060229984 CVE DE RASTREO:02107200021000820250102219127 REF:0229984 RFC VLE060918B86 IVA: 0.00 | G8: $20,721.48 | H8: 45658 | I8: LEASING VEHICULOS
A9: Telefono, internet | B9: TRASPASO A CUENTA DE TERCEROS 0003012025 IVA:00000000.00 , A LA CUENTA: 0259644345 Pago factura QCOME5361 AL R.F.C. LAN120809LR8 | G9: $17,400.00 | H9: 45658 | I9: TELEFONO E INTERNET
A10: Arrendamiento a personas fisicas resid nal | B10: COMPRA ORDEN DE PAGO SPEI 030125 =REFERENCIA CTA/CLABE: 021680040571712668, BXI SPEI BCO:021 BENEF:ANGEL OROSCO ANGELES (DATO NO VERIFICADO POR ESTA INSTITUCIÓN), Pago facturas 6324 y 6325 CVE RASTREO: 7875APR2202501033682619257 RFC: No capturado IVA: 000000000000.00 HSBC HORA LIQ: 17:22:27 | G10: $43,376.18 | H10: 45658 | I10: IMPRESIONES QUERETARO
A11: Comisiones bancarias | B11: COMISION ORDEN DE PAGO SPEI REFERENCIA: 030125 | G11: $5.00 | H11: 45658 | I11: COMISIONES BANCARIAS
A12: Comisiones bancarias | B12: I.V.A. ORDEN DE PAGO SPEI REFERENCIA: 0030125 | G12: $0.80 | H12: 45658 | I12: COMISIONES BANCARIAS
A13: Viaticos y gastos de viaje | B13: COMPRA ORDEN DE PAGO SPEI 030125 =REFERENCIA CTA/CLABE: 002580904396504698, BXI SPEI BCO:002 BENEF:BEATRIZ IRENE MEDELLIN ROSALE (DATO NO VERIFICADO POR ESTA INSTITUCIÓN), Pago de facturas FB6 B9F y 77D CVE RASTREO: 7875APR1202501033682637247 RFC: No capturado IVA: 000000000000.00 BANAMEX HORA LIQ: 17:26:47 | G13: $13,055.80 | H13: 45658 | I13: EQUIPAMIENTO Y RECARGAS
... A21: Comisiones bancarias | B21: I.V.A. ORDEN DE PAGO SPEI REFERENCIA: 030125 | G21: $0.80 | H21: 45658 | I21: COMISIONES BANCARIAS
B22: TRASPASO A CUENTA DE TERCEROS 0003012025 IVA:00000000.00 , A LA CUENTA: 1095347243 Pago factura Z07814 AL R.F.C. GSH191022B67 | G22: $2,924.39 | H22: 45658
A23: Viaticos y gastos de viaje | B23: COMPRA ORDEN DE PAGO SPEI 030125 =REFERENCIA CTA/CLABE: 646180401000017358, BXI SPEI BCO:646 BENEF:EFECTIVALE FINTECH (DATO NO VERIFICADO POR ESTA INSTITUCIÓN), 0168731 CVE RASTREO: 7875APR2202501033682707978 RFC: No capturado IVA: 000000000000.00 STP HORA LIQ: 17:45:13 | G23: $176,706.64 | H23: 45658 | I23: VIATICOS
A24: Comisiones bancarias | B24: COMISION ORDEN DE PAGO SPEI REFERENCIA: 030125 | G24: $5.00 | H24: 45658 | I24: COMISIONES BANCARIAS
A25: Comisiones bancarias | B25: I.V.A. ORDEN DE PAGO SPEI REFERENCIA: 030125 | G25: $0.80 | H25: 45658 | I25: COMISIONES BANCARIAS
A26: Viaticos y gastos de viaje | B26: COMPRA ORDEN DE PAGO SPEI 030125 =REFERENCIA CTA/CLABE: 021180042182424610, BXI SPEI BCO:021 BENEF:EFECTIVALE S DE RL DE CV (DATO NO VERIFICADO POR ESTA INSTITUCIÓN), C0180251001COMBTAR00 CVE RASTREO: 7875APR2202501033682724845 RFC: No capturado IVA: 000000000000.00 HSBC HORA LIQ: 17:49:51 | G26: $10,215.34 | H26: 45658 | I26: VIATICOS
A27: Comisiones bancarias | B27: COMISION ORDEN DE PAGO SPEI REFERENCIA: 030125 | G27: $5.00 | H27: 45658 | I27: COMISIONES BANCARIAS
A28: Comisiones bancarias | B28: I.V.A. ORDEN DE PAGO SPEI REFERENCIA: 030125 | G28: $0.80 | H28: 45658 | I28: COMISIONES BANCARIAS
A29: Sueldos y salarios | B29: COMPRA ORDEN DE PAGO SPEI 030125 =REFERENCIA CTA/CLABE: 012180001191796583, BXI SPEI BCO:012 BENEF:CONSORCIO EMPRENDEDOR LA FINCA (DATO NO VERIFICADO POR ESTA INSTITUCIÓN), Pago factura CVE RASTREO: 7875APR1202501033682754690 RFC: CEF180301697 IVA: 000000000000.00 BBVA MEXICO HORA LIQ: 18:04:53 | G29: $49,926.65 | H29: 45658 | I29: NOMINA
A30: Comisiones bancarias | B30: COMISION ORDEN DE PAGO SPEI REFERENCIA: 030125 | G30: $5.00 | H30: 45658 | I30: COMISIONES BANCARIAS
A31: Comisiones bancarias | B31: I.V.A. ORDEN DE PAGO SPEI REFERENCIA: 030125 | G31: $0.80 | H31: 45658 | I31: COMISIONES BANCARIAS
A32: Sueldos y salarios | B32: COMPRA ORDEN DE PAGO SPEI 030125 =REFERENCIA CTA/CLABE: 012180001197280747, BXI SPEI BCO:012 BENEF:SERV INDUSTRIALES ENDENSA (DATO NO VERIFICADO POR ESTA INSTITUCIÓN), Pago factura CVE RASTREO: 7875APR2202501033682795035 RFC: SIE210526EWA IVA: 000000000000.00 BBVA MEXICO HORA LIQ: 18:15:41 | G32: $13,890.77 | H32: 45658 | I32: NOMINA
A33: Comisiones bancarias | B33: COMISION ORDEN DE PAGO SPEI REFERENCIA: 030125 | G33: $5.00 | H33: 45658 | I33: COMISIONES BANCARIAS
A34: Comisiones bancarias | B34: I.V.A. ORDEN DE PAGO SPEI REFERENCIA: 030125 | G34: $0.80 | H34: 45658 | I34: COMISIONES BANCARIAS
... A87: Comisiones bancarias | B87: I.V.A. ORDEN DE PAGO SPEI REFERENCIA: 090125 | G87: $0.80 | H87: 45658 | I87: COMISIONES BANCARIAS
B88: TRASPASO A CUENTA DE TERCEROS 0009012025 IVA:00000000.00 , A LA CUENTA: 1227275781 PD UPS APODACA NL SEM02 AL R.F.C. CUMS810521CG2 | G88: $2,714.25 | H88: 45658 | I88: PASES DE CAJA (FONDOS CLIENTES)
A89: Sueldos y salarios | B89: COMPRA ORDEN DE PAGO SPEI 090125 =REFERENCIA CTA/CLABE: 012180001191796583, BXI SPEI BCO:012 BENEF:CONSORCIO EMPRENDEDOR LA FINCA (DATO NO VERIFICADO POR ESTA INSTITUCIÓN), Pago factura CVE RASTREO: 7875APR1202501093695401128 RFC: CEF180301697 IVA: 000000000000.00 BBVA MEXICO HORA LIQ: 12:51:56 | G89: $126,527.93 | H89: 45658 | I89: NOMINA
A90: Comisiones bancarias | B90: COMISION ORDEN DE PAGO SPEI REFERENCIA: 090125 | G90: $5.00 | H90: 45658 | I90: COMISIONES BANCARIAS
A91: Comisiones bancarias | B91: I.V.A. ORDEN DE PAGO SPEI REFERENCIA: 090125 | G91: $0.80 | H91: 45658 | I91: COMISIONES BANCARIAS
A92: Sueldos y salarios | B92: COMPRA ORDEN DE PAGO SPEI 090125 =REFERENCIA CTA/CLABE: 012180001197280747, BXI SPEI BCO:012 BENEF:SERV INDUSTRIALES ENDENSA (DATO NO VERIFICADO POR ESTA INSTITUCIÓN), Pago factura CVE RASTREO: 7875APR2202501093695409350 RFC: SIE210526EWA IVA: 000000000000.00 BBVA MEXICO HORA LIQ: 12:54:41 | G92: $69,034.58 | H92: 45658 | I92: NOMINA
A93: Comisiones bancarias | B93: COMISION ORDEN DE PAGO SPEI REFERENCIA: 090125 | G93: $5.00 | H93: 45658 | I93: COMISIONES BANCARIAS
A94: Comisiones bancarias | B94: I.V.A. ORDEN DE PAGO SPEI REFERENCIA: 090125 | G94: $0.80 | H94: 45658 | I94: COMISIONES BANCARIAS
A95: Dictamenes | B95: COMPRA ORDEN DE PAGO SPEI 090125 =REFERENCIA CTA/CLABE: 030470900013178030, BXI SPEI BCO:030 BENEF:JUVENAL LEAL HERNANDEZ (DATO NO VERIFICADO POR ESTA INSTITUCIÓN), Dict electrico pepsico cedis 712 769 y n CVE RASTREO: 7875APR2202501093695579909 RFC: No capturado IVA: 000000000000.00 BAJIO HORA LIQ: 13:48:39 | G95: $12,488.62 | H95: 45658 | I95: DICTAMENES
A96: Comisiones bancarias | B96: COMISION ORDEN DE PAGO SPEI REFERENCIA: 090125 | G96: $5.00 | H96: 45658 | I96: COMISIONES BANCARIAS
A97: Comisiones bancarias | B97: I.V.A. ORDEN DE PAGO SPEI REFERENCIA: 090125 | G97: $0.80 | H97: 45658 | I97: COMISIONES BANCARIAS
A98: Dictamenes | B98: COMPRA ORDEN DE PAGO SPEI 090125 =REFERENCIA CTA/CLABE: 030470900013178030, BXI SPEI BCO:030 BENEF:JUVENAL LEAL HERNANDEZ (DATO NO VERIFICADO POR ESTA INSTITUCIÓN), VERIFICACION ELECTRICA PEPSICO PATZCUARO CVE RASTREO: 7875APR2202501093695588426 RFC: No capturado IVA: 000000000000.00 BAJIO HORA LIQ: 13:51:45 | G98: $13,346.62 | H98: 45658 | I98: DICTAMENES
A99: Comisiones bancarias | B99: COMISION ORDEN DE PAGO SPEI REFERENCIA: 090125 | G99: $5.00 | H99: 45658 | I99: COMISIONES BANCARIAS
...

Sheet NOTAS
A2: CORNEJO JIMENEZ MARLEN | B2: Está asignada a 3 zonas, se realizó una división de su monto de nómina en cada mes
B3: No tiene nómina interna en abril
A4: CRUZ RODRIGUEZ MARINA CRISTHEL | B4: No tiene zona designada, se asignó de acuerdo a la zona de nómina de los archivos de nom externa
A5: GARCIA CORTES BELLMAR ALONSO | B5: No tiene zona designada, se asignó de acuerdo a la zona de nómina de los archivos de nom externa
A6: HIDALGO RODRIGUEZ JESUS EULALIO | B6: No tiene zona designada, se asignó de acuerdo a la zona de nómina de los archivos de nom externa
A7: LEDEZMA LONGORIA DANIKA (MULTIZONA) | B7: Está asignada a 3 zonas, se realizó una división de su monto de nómina en cada mes
A8: MACIAS BERNACHE ESMERALDA GALILEA | B8: No tiene zona designada, se asignó de acuerdo a la zona de nómina de los archivos de nom externa
A9: MIRELES ORNELAS JORGE | B9: No tiene zona designada, se asignó de acuerdo a la zona de nómina de los archivos de nom externa
A10: MORENO CAMPOS ARMANDO | B10: No tiene zona designada, se asignó de acuerdo a la zona de nómina de los archivos de nom externa
A11: MURO JIMENEZ GERARDO AUGUSTO | B11: No tiene zona designada, se asignó de acuerdo a la zona de nómina de los archivos de nom externa
A12: PEREZ LOPEZ LUIS GUSTAVO | B12: No tiene zona designada, se asignó de acuerdo a la zona de nómina de los archivos de nom externa
A14: MORENO CATARINO VICTOR URIEL | B14: EN EL ARCHIVO DE MARIO ESTÁ COMO NORTE Y EN EL BUDGET COMO NOROESTE
A15: Las depreciaciones de equipo de cómputo y mob de oficina se dividen por headcount, la de automoviles se manda a ops
A16: Se hizo reconteo de headcount para división de egresos a partir de depreciaciones | K16: LAE
A17: PREGUNTAR POR CONCEPTO devolucion en febrero | K17: 4 MESES EN CONCLUIRSE
A18: SE agregó LAE como dirección | K18: EMPIEZA egresos bajos y sbe
A19: preguntar de PAGO DE INTERESES 88059964-089590332 de 7mil sobre si es comision o intereses | K19: 12 millones de inver
A20: preguntar de loc box | B20: (se mandó 50% a técnico y 50% a LAE) | K20: 250 mil de renta mensual por construir
A21: PENDIENTE UNIFORMES, VER QUIEN LOS USA | K21: costo financiero: 1% para factoraje hasta 2% capital mint
A22: SE ELIMINÓ BBVA855 POR -0,17 | K22: minimizar gasto inecesario de pagar rentas por no hacer nada
A23: Arquitectura - Jorge Gonzalez Hernandez Magri MacBook Pro 14" MDE14E/A Chip M5 CPU10 GPU10 16GB 1TB Negro Espacial | C23: REVISAR EL EGRESSO DE SISTEMAS EMPRESARIALES DABO, ES DE 1981 Y EL GASTO FUE DE 45 K | K23: minimizar riesgo de subidas de precios y servicios
A24: KORNER SALES, VIATICOS TIENEN 719 Y EN CAMSA HAY 619,83 | K24: menor costo financiero
A25: preguntar de BANCO MONEX S.A. INSTITUCION DE BANCA MULTIPLE, MONEX GRUPO FINANCIERO fideicomiso | K25: una vez empezando no se para
A26: Revisar Belanea Mexico recarga de Arturo Ret, es posible que ya esté en dispersiones si el gasto se hizo con clara | K26: componente mas grande: mano de obra
K28: safety net: ya no autorizo mas pagos cuando llego a 1.5 mill

Sheet DF_LIMPIO1
A1: Fecha | B1: Tipo | C1: Número | D1: Concepto | E1: Referencia | F1: Cargos | G1: Clasf Efs | H1: Abonos | I1: Saldo
A2: 01/Ene/2026 | B2: Diario | C2: 297 | D2: NOMINA QUINCENAL ENERO 2026 | F2: 146471.83 | G2: Sueldos y salarios | H2: 0 | I2: 146471.83
A3: 01/Ene/2026 | B3: Diario | C3: 500 | D3: PROVISION IMSS ENERO 2026 | E3: IMSS | F3: 13833.01 | G3: Cuotas al IMSS | H3: 0 | I3: 13833.01
A4: 01/Ene/2026 | B4: Diario | C4: 501 | D4: IMPUESTO SOBRE NOMINA | E4: ISN | F4: 3569 | G4: Impuesto estatal sobre nóminas | H4: 0 | I4: 3569
A5: 01/Ene/2026 | B5: Diario | C5: 280 | D5: UNIDAD DE NEGOCIO NIBER | E5: F-5904 | F5: 179.18 | G5: Servicios administrativos | H5: 0 | I5: 179.18
A6: 01/Ene/2026 | B6: Diario | C6: 280 | D6: UNIDAD DE NEGOCIO NIBER | E6: F-5900 | F6: 1260 | G6: Servicios administrativos | H6: 0 | I6: 1439.18
A7: 01/Ene/2026 | B7: Diario | C7: 280 | D7: UNIDAD DE NEGOCIO NIBER | E7: F-5903 | F7: 2616 | G7: Servicios administrativos | H7: 0 | I7: 4055.18
A8: 01/Ene/2026 | B8: Diario | C8: 280 | D8: UNIDAD DE NEGOCIO NIBER | E8: F-5907 | F8: 51405.6 | G8: Servicios administrativos | H8: 0 | I8: 55460.78
A9: 01/Ene/2026 | B9: Diario | C9: 280 | D9: UNIDAD DE NEGOCIO NIBER | E9: F-5901 | F9: 215465.96 | G9: Servicios administrativos | H9: 0 | I9: 270926.74
A10: 01/Ene/2026 | B10: Diario | C10: 280 | D10: UNIDAD DE NEGOCIO NIBER | E10: F-5908 | F10: 228035.56 | G10: Servicios administrativos | H10: 0 | I10: 498962.3
A11: 01/Ene/2026 | B11: Diario | C11: 288 | D11: BRYTALAR CONSULTORES EN INGENIERIA Y OBRAS | E11: F-766 | F11: 4613.53 | G11: Servicios administrativos | H11: 0 | I11: 503575.83
A12: 01/Ene/2026 | B12: Diario | C12: 288 | D12: BRYTALAR CONSULTORES EN INGENIERIA Y OBRAS | E12: F-770 | F12: 4613.53 | G12: Servicios administrativos | H12: 0 | I12: 508189.36
A13: 01/Ene/2026 | B13: Diario | C13: 288 | D13: BRYTALAR CONSULTORES EN INGENIERIA Y OBRAS | E13: F-771 | F13: 4613.53 | G13: Servicios administrativos | H13: 0 | I13: 512802.89
A14: 01/Ene/2026 | B14: Diario | C14: 288 | D14: BRYTALAR CONSULTORES EN INGENIERIA Y OBRAS | E14: F-778 | F14: 4613.53 | G14: Servicios administrativos | H14: 0 | I14: 517416.42
... A103: 01/Ene/2026 | B103: Diario | C103: 287 | D103: GRUMINER | E103: F-430 | F103: 25000 | G103: Seguros y fianzas | H103: 0 | I103: 25000
A104: 02/Ene/2026 | B104: Egresos | C104: 2 | D104: SEGUROS BANORTE | E104: 48728 | F104: 3608.33 | G104: Seguros y fianzas | H104: 0 | I104: 28608.33
A105: 13/Ene/2026 | B105: Egresos | C105: 79 | D105: SEGUROS BANORTE | E105: 48938 | F105: 53535 | G105: Seguros y fianzas | H105: 0 | I105: 82143.33
A106: 27/Ene/2026 | B106: Egresos | C106: 148 | D106: SEGUROS Y FIANZAS | E106: 49147 | F106: 5700.83 | G106: Seguros y fianzas | H106: 0 | I106: 87844.16
A107: 01/Ene/2026 | B107: Diario | C107: 262 | D107: CUOTAS Y SUSCRIPCIONES | E107: F-VARIOS | F107: 585.56 | G107: Cuotas y suscripciones | H107: 0 | I107: 585.56
A108: 01/Ene/2026 | B108: Diario | C108: 276 | D108: EDGAR ALONSO AGUILAR NEGRETE | E108: F-1615 | F108: 1227.1 | G108: Cuotas y suscripciones | H108: 0 | I108: 1812.66
A109: 01/Ene/2026 | B109: Diario | C109: 276 | D109: EDGAR ALONSO AGUILAR NEGRETE | E109: F-1632 | F109: 4275 | G109: Cuotas y suscripciones | H109: 0 | I109: 6087.66
A110: 01/Ene/2026 | B110: Diario | C110: 276 | D110: EDGAR ALONSO AGUILAR NEGRETE | E110: F-1620 | F110: 18254.66 | G110: Cuotas y suscripciones | H110: 0 | I110: 24342.32
A111: 01/Ene/2026 | B111: Diario | C111: 276 | D111: IMR SOFTWARE | E111: F-4614 | F111: 4500 | G111: Cuotas y suscripciones | H111: 0 | I111: 28842.32
A112: 01/Ene/2026 | B112: Diario | C112: 276 | D112: IMR SOFTWARE | E112: F-2586 | F112: 3190 | G112: Cuotas y suscripciones | H112: 0 | I112: 32032.32
A113: 01/Ene/2026 | B113: Diario | C113: 276 | D113: ONLINE CARRER CENTER MEXICO | E113: F-3101 | F113: 3864 | G113: Cuotas y suscripciones | H113: 0 | I113: 35896.32
A114: 01/Ene/2026 | B114: Diario | C114: 281 | D114: GOOGLE MX | E114: F-2523 | F114: -5233.75 | G114: Cuotas y suscripciones | H114: 0 | I114: 30662.57
A115: 01/Ene/2026 | B115: Diario | C115: 281 | D115: GOOGLE MX | E115: F-2524 | F115: -3274.32 | G115: Cuotas y suscripciones | H115: 0 | I115: 27388.25
A116: 01/Ene/2026 | B116: Diario | C116: 281 | D116: GOOGLE MX | E116: F-5241 | F116: 8508.07 | G116: Cuotas y suscripciones | H116: 0 | I116: 35896.32
A117: 01/Ene/2026 | B117: Diario | C117: 281 | D117: GOOGLE MX | E117: F-7673 | F117: 8620.69 | G117: Cuotas y suscripciones | H117: 0 | I117: 44517.01
A118: 01/Ene/2026 | B118: Diario | C118: 282 | D118: JESUS ALEJANDRO GALLARZA ORTEGA | E118: F- | F118: 46093.1 | G118: Cuotas y suscripciones | H118: 0 | I118: 90610.11
A119: 16/Ene/2026 | B119: Egresos | C119: 106 | D119: PAGO INTERESES XEPELIN | E119: 49013 | F119: 7067.24 | G119: Cuotas y suscripciones | H119: 0 | I119: 97677.35
A120: 22/Ene/2026 | B120: Egresos | C120: 220 | D120: INVOICE | E120: BBVA793 | F120: 3052.96 | G120: Cuotas y suscripciones | H120: 0 | I120: 100730.31
A121: 22/Ene/2026 | B121: Egresos | C121: 235 | D121: INVOICE | E121: BBVAUSD | F121: 14460.38 | G121: Cuotas y suscripciones | H121: 0 | I121: 115190.69
A122: 22/Ene/2026 | B122: Egresos | C122: 236 | D122: INVOICE | E122: BBVAUSD | F122: 28237.34 | G122: Cuotas y suscripciones | H122: 0 | I122: 143428.03
A123: 23/Ene/2026 | B123: Egresos | C123: 237 | D123: INVOICE | E123: BBVAUSD | F123: 6454.65 | G123: Cuotas y suscripciones | H123: 0 | I123: 149882.68
A124: 23/Ene/2026 | B124: Egresos | C124: 238 | D124: INVOICE | E124: BBVAUSD | F124: 2422.94 | G124: Cuotas y suscripciones | H124: 0 | I124: 152305.62
A125: 29/Ene/2026 | B125: Egresos | C125: 241 | D125: BBVAUSD | E125: BBVAUSD | F125: 86195.46 | G125: Cuotas y suscripciones | H125: 0 | I125: 238501.08
A126: 29/Ene/2026 | B126: Egresos | C126: 252 | D126: BBVAUSD ARIBA | E126: BBVAUSD | F126: 2478.51 | G126: Cuotas y suscripciones | H126: 0 | I126: 240979.59
A127: 01/Ene/2026 | B127: Diario | C127: 292 | D127: MARIA SONIA RODRIGUEZ GONZALEZ | E127: F-3115 | F127: 32000 | G127: Fletes y acarreos | H127: 0 | I127: 32000
A128: 01/Ene/2026 | B128: Diario | C128: 269 | D128: UNIFORMES | E128: F-VARIOS | F128: 6378.42 | G128: Uniformes | H128: 0 | I128: 6378.42
...

Sheet DF_LIMPIO2
A1: CATEGORIA_NETSUITE | B1: Concepto | C1: IS | D1: ÁREA | E1: ZONA PPTO | F1: EMPLEADO | G1: MONTO | H1: PERIODO | I1: AREA | J1: ZONA | K1: PCT_POND | L1: Fecha | M1: Tipo | N1: Número | O1: Clasf Efs | P1: ID SGN | Q1: PUESTO | R1: PAGADORA | S1: Columna 19 | T1: Columna 20 | U1: Columna 21 | V1: Columna 22 | W1: Columna 23 | X1: Columna 24 | Y1: Columna 25
A2: Otros gastos generales | B2: ACTIVE LEASING | C2: OTROS Facturación / GASTOS | D2: LAE | G2: 7343.97 | L2: 01/Feb/2026 | M2: Diario | N2: 18 | O2: Arrendamiento a pers morales residtes nal | S2: Equipo médico
A3: Asistencia Legal | B3: ADMINISTRACION N23 | C3: GASTOS DE ADMINISTRACIÓN | D3: COMERCIAL | G3: 344.82 | L3: 01/Feb/2026 | M3: Diario | N3: 34 | O3: Servicios administrativos
A4: Uniformes | B4: ALBERTO SANCHEZ BENAVIDES | C4: GASTOS DE ADMINISTRACIÓN | D4: OTROS | G4: 830 | L4: 01/Feb/2026 | M4: Diario | N4: 39 | O4: Uniformes
A5: Uniformes | B5: ALBERTO SANCHEZ BENAVIDES | C5: GASTOS DE ADMINISTRACIÓN | D5: OTROS | G5: 4718 | L5: 01/Feb/2026 | M5: Diario | N5: 39 | O5: Uniformes
A6: Uniformes | B6: ALBERTO SANCHEZ BENAVIDES | C6: GASTOS DE ADMINISTRACIÓN | D6: OTROS | G6: 10518 | L6: 01/Feb/2026 | M6: Diario | N6: 39 | O6: Uniformes
A7: Otros gastos generales | B7: ALL PHARMA | C7: GASTOS DE ADMINISTRACIÓN | D7: RH | G7: 270.98 | L7: 01/Feb/2026 | M7: Diario | N7: 25 | O7: Insumos para control de incendios
A8: Amortizacion acumulada de Software | B8: AMORTIZACION | C8: GASTOS DE ADMINISTRACIÓN | D8: FINANZAS | G8: 51069.485 | L8: 01/Feb/2026 | M8: Diario | N8: 502 | O8: Amortización acumulada de Software
A9: Amortizacion acumulada de Software | B9: AMORTIZACION | C9: COGS | D9: OPERACIONES | G9: 51069.485 | L9: 01/Feb/2026 | M9: Diario | N9: 502
A10: Arrendamiento a pers fisicas residtes nal | B10: ANGEL OROSCO ANGELES | C10: POR CLASIFICAR | D10: OTROS | G10: 17285.92 | L10: 01/Feb/2026 | M10: Diario | N10: 31 | O10: Papelería y artículos de oficina
A11: Arrendamiento a pers fisicas residtes nal | B11: ANGEL OROSCO ANGELES | C11: POR CLASIFICAR | D11: OTROS | G11: 22480.9 | L11: 01/Feb/2026 | M11: Diario | N11: 31 | O11: Papelería y artículos de oficina
A12: Mantenimiento y conservacion | B12: ARMANDO HERRERA VELAZQUEZ | C12: GASTOS DE ADMINISTRACIÓN | D12: BRAND BUILDING | G12: 102.80985 | L12: 01/Feb/2026 | M12: Diario | N12: 29 | O12: Mantenimiento y conservación
A13: Mantenimiento y conservacion | B13: ARMANDO HERRERA VELAZQUEZ | C13: GASTOS DE ADMINISTRACIÓN | D13: COMERCIAL | G13: 219.63923
A14: Mantenimiento y conservacion | B14: ARMANDO HERRERA VELAZQUEZ | C14: GASTOS DE ADMINISTRACIÓN | D14: DIRECTIVO | G14: 74.770803
A15: Mantenimiento y conservacion | B15: ARMANDO HERRERA VELAZQUEZ | C15: GASTOS DE ADMINISTRACIÓN | D15: FINANZAS | G15: 98.136679
A16: Mantenimiento y conservacion | B16: ARMANDO HERRERA VELAZQUEZ | C16: COGS | D16: OPERACIONES | G16: 1453.3575
A17: Mantenimiento y conservacion | B17: ARMANDO HERRERA VELAZQUEZ | C17: GASTOS DE ADMINISTRACIÓN | D17: RH | G17: 74.770803
A18: Mantenimiento y conservacion | B18: ARMANDO HERRERA VELAZQUEZ | C18: GASTOS DE ADMINISTRACIÓN | D18: TÉCNICO | G18: 537.41515
A19: Otros gastos generales | B19: ARRENDADORA HMS | C19: GASTOS DE ADMINISTRACIÓN | D19: OTROS | G19: 8900 | L19: 01/Feb/2026 | M19: Diario | N19: 21 | O19: Cuotas y suscripciones
A20: Gestoría | B20: ARTURO RAMSES CONTRERAS TORRES | C20: COGS | D20: OPERACIONES | G20: 56473.56 | L20: 01/Feb/2026 | M20: Diario | N20: 19 | O20: Capacitaciones
A21: Transportación terrestre | B21: AUTOMOVILES PRO SNOP | C21: COGS | D21: OPERACIONES | G21: 341293.1 | L21: 01/Feb/2026 | M21: Diario | N21: 187 | O21: Arrendamiento a pers morales residtes nal
A22: Transportación terrestre | B22: AUTOMOVILES PRO SNOP | C22: COGS | D22: OPERACIONES | G22: 168490 | L22: 27/Feb/2026 | M22: Egresos | N22: 258 | O22: GASTOS NO DEDUCIBLES
A23: OTROS EGRESOS FINAN | B23: BANCO MONEX S.A. INSTITUCION DE BANCA MULTIPLE, MONEX GRUPO FINANCIERO | C23: OTROS Facturación / GASTOS | D23: LAE | G23: 7500 | L23: 01/Feb/2026 | M23: Diario | N23: 34 | O23: Servicios administrativos
A24: Otros gastos generales | B24: BANCO MONEX S.A. INSTITUCION DE BANCA MULTIPLE, MONEX GRUPO FINANCIERO | C24: GASTOS DE ADMINISTRACIÓN | D24: FINANZAS | G24: 140000 | L24: 01/Feb/2026 | M24: Diario | N24: 34 | O24: Servicios administrativos
A25: Insumos para cursos | B25: BEATRIZ IRENE MEDELLIN ROSALES | C25: COGS | D25: OPERACIONES | G25: 2160 | L25: 01/Feb/2026 | M25: Diario | N25: 27 | O25: Insumos para cursos
A26: Viaticos y gastos de viaje | B26: BELANEA MEXICO | C26: GASTOS DE ADMINISTRACIÓN | D26: TÉCNICO | F26: Arturo Retana | G26: 129.31 | L26: 01/Feb/2026 | M26: Diario | N26: 37 | O26: Teléfono, internet
A27: Otros gastos generales | B27: BEPENSA LEASING | C27: GASTOS DE ADMINISTRACIÓN | D27: OTROS | G27: 114992.67 | L27: 01/Feb/2026 | M27: Diario | N27: 18 | O27: Arrendamiento a pers morales residtes nal
A28: Otros gastos generales | B28: BEPENSA LEASING | C28: GASTOS DE ADMINISTRACIÓN | D28: OTROS | G28: 0.01 | L28: 01/Feb/2026 | M28: Egresos | N28: 1 | O28: GASTOS NO DEDUCIBLES
A29: Viaticos y gastos de viaje | B29: BOLETOS DE AVION | C29: COGS | G29: 62245.98 | L29: 01/Feb/2026 | M29: Diario | N29: 1 | O29: Boletos de Avión
A30: Insumos para cursos | B30: BOXES & MORE MJ24 | C30: COGS | D30: OPERACIONES | G30: 2094.93 | L30: 01/Feb/2026 | M30: Diario | N30: 28 | O30: Limpieza
A31: Dictamenes | B31: BRENDA ELIZABETH REYES ROMERO | C31: COGS | D31: OPERACIONES | G31: 9500 | L31: 01/Feb/2026 | M31: Diario | N31: 23 | O31: Dictamenes
A32: Sueldos y salarios | B32: BRYTALAR CONSULTORES EN INGENIERIA Y OBRAS | G32: 4613.53 | L32: 01/Feb/2026 | M32: Diario | N32: 23 | O32: Dictamenes
A33: Sueldos y salarios | B33: BRYTALAR CONSULTORES EN INGENIERIA Y OBRAS | G33: 4619.48 | L33: 01/Feb/2026 | M33: Diario | N33: 23 | O33: Dictamenes
A34: Sueldos y salarios | B34: BRYTALAR CONSULTORES EN INGENIERIA Y OBRAS | G34: 4619.48 | L34: 01/Feb/2026 | M34: Diario | N34: 23 | O34: Dictamenes
A35: Sueldos y salarios | B35: BRYTALAR CONSULTORES EN INGENIERIA Y OBRAS | G35: 4619.48 | L35: 01/Feb/2026 | M35: Diario | N35: 23 | O35: Dictamenes
A36: Sueldos y salarios | B36: BRYTALAR CONSULTORES EN INGENIERIA Y OBRAS | G36: 79715.31 | L36: 01/Feb/2026 | M36: Diario | N36: 23 | O36: Dictamenes
A37: Sueldos y salarios | B37: BRYTALAR CONSULTORES EN INGENIERIA Y OBRAS | G37: 81582.86 | L37: 01/Feb/2026 | M37: Diario | N37: 23 | O37: Dictamenes
A38: Honorarios a personas fis residentes nal | B38: CAMSA SOLUCIONES FISCALES | C38: GASTOS DE ADMINISTRACIÓN | D38: FINANZAS | G38: 21340.52 | L38: 01/Feb/2026 | M38: Diario | N38: 33 | O38: Servicios administrativos
A39: Comisiones bancarias | B39: CAPITALMINT ADM | C39: GASTOS DE ADMINISTRACIÓN | D39: FINANZAS | G39: 187500 | L39: 01/Feb/2026 | M39: Diario | N39: 24 | O39: GESTION DE EVENTOS
A40: Viaticos y gastos de viaje | B40: CASETAS | C40: COGS | G40: 44230.46 | L40: 01/Feb/2026 | M40: Diario | N40: 2 | O40: Casetas y estacionamientos
...

Sheet DF_LIMPIO3
A1: CATEGORIA_NETSUITE | B1: Concepto | C1: IS | D1: ÁREA | E1: ZONA PPTO | F1: EMPLEADO | G1: MONTO | H1: PERIODO | I1: AREA | J1: ZONA | K1: PCT_POND | L1: Fecha | M1: Tipo | N1: Número | O1: Clasf Efs | P1: ID SGN | Q1: PUESTO | R1: PAGADORA | S1: Columna 19 | T1: Columna 20 | U1: Columna 21 | V1: Columna 22 | W1: Columna 23 | X1: Columna 24 | Y1: Columna 25
A2: Papeleria y articulos de oficina | B2: ABASTECEDORA DE OFICINAS | C2: COGS | D2: OPERACIONES | G2: 2771.61 | L2: 01/Mar/2026 | M2: Diario | N2: 241 | O2: Papelería y artículos de oficina
A3: Otros gastos generales | B3: ACTIVE LEASING | C3: GASTOS DE ADMINISTRACIÓN | D3: COMERCIAL | G3: 7343.97 | L3: 01/Mar/2026 | M3: Diario | N3: 228 | O3: Arrendamiento a pers morales residtes nal
A4: Asistencia Legal | B4: ADMINISTRACION N23 | C4: GASTOS DE ADMINISTRACIÓN | D4: COMERCIAL | G4: 1000 | L4: 06/Mar/2026 | M4: Egresos | N4: 61 | O4: GASTOS NO DEDUCIBLES
A5: Asistencia Legal | B5: ADMINISTRACION N23 | C5: GASTOS DE ADMINISTRACIÓN | D5: COMERCIAL | G5: 352 | L5: 06/Mar/2026 | M5: Egresos | N5: 62 | O5: GASTOS NO DEDUCIBLES
A6: Asistencia Legal | B6: ADMINISTRACION N23 | C6: GASTOS DE ADMINISTRACIÓN | D6: COMERCIAL | G6: 344.82 | L6: 01/Mar/2026 | M6: Diario | N6: 229 | O6: Asistencia Legal
A7: Asistencia Legal | B7: ADMINISTRACION N23 | C7: GASTOS DE ADMINISTRACIÓN | D7: COMERCIAL | G7: 10000 | L7: 01/Mar/2026 | M7: Diario | N7: 229 | O7: Asistencia Legal
A8: Asistencia Legal | B8: ADMINISTRACION N23 | C8: GASTOS DE ADMINISTRACIÓN | D8: COMERCIAL | G8: 21893.46 | L8: 01/Mar/2026 | M8: Diario | N8: 229 | O8: Asistencia Legal
A9: Uniformes | B9: ALBERTO SANCHEZ BENAVIDES | C9: GASTOS DE ADMINISTRACIÓN | D9: OTROS | G9: 4150 | L9: 01/Mar/2026 | M9: Diario | N9: 241 | O9: Papelería y artículos de oficina
A10: Amortizacion acumulada de Software | B10: AMORTIZACION | C10: GASTOS DE ADMINISTRACIÓN | D10: FINANZAS | G10: 51889.725 | L10: 01/Mar/2026 | M10: Diario | N10: 401 | O10: Amortización acumulada de Software
A11: Amortizacion acumulada de Software | B11: AMORTIZACION | C11: COGS | D11: OPERACIONES | G11: 51889.725 | L11: 01/Mar/2026 | M11: Diario | N11: 401
A12: SIN CLASIFICAR | B12: ANA LUCIA PEREZ MENDOZA | G12: 1468 | L12: 01/Mar/2026 | M12: Diario | N12: 241 | O12: Papelería y artículos de oficina
A13: Arrendamiento a pers fisicas residtes nal | B13: ANGEL OROSCO ANGELES | C13: POR CLASIFICAR | D13: OTROS | G13: 3092.07 | L13: 01/Mar/2026 | M13: Diario | N13: 228 | O13: Arrendamiento a pers físicas residtes nal
A14: Arrendamiento a pers fisicas residtes nal | B14: ANGEL OROSCO ANGELES | C14: POR CLASIFICAR | D14: OTROS | G14: 49042.22 | L14: 01/Mar/2026 | M14: Diario | N14: 228 | O14: Arrendamiento a pers físicas residtes nal
A15: Arrendamiento a pers fisicas residtes nal | B15: ANGEL OROSCO ANGELES | C15: POR CLASIFICAR | D15: OTROS | G15: 3756.68 | L15: 01/Mar/2026 | M15: Diario | N15: 228 | O15: Arrendamiento a pers morales residtes nal
A16: Arrendamiento a pers fisicas residtes nal | B16: ANGEL OROSCO ANGELES | C16: POR CLASIFICAR | D16: OTROS | G16: 57369.14 | L16: 01/Mar/2026 | M16: Diario | N16: 228 | O16: Arrendamiento a pers morales residtes nal
A17: SIN CLASIFICAR | B17: ARMANDO RIVERA LOPEZ | G17: 1500 | L17: 01/Mar/2026 | M17: Diario | N17: 243 | O17: Servicios administrativos
A18: Otros gastos generales | B18: ARRENDADORA HMS | C18: GASTOS DE ADMINISTRACIÓN | D18: OTROS | G18: 8900 | L18: 01/Mar/2026 | M18: Diario | N18: 228 | O18: Arrendamiento a pers morales residtes nal
A19: SIN CLASIFICAR | B19: ARTICULOS DE ELECTRINICOS | G19: 1807.76 | L19: 01/Mar/2026 | M19: Diario | N19: 213 | O19: Mantenimiento y conservación
A20: SIN CLASIFICAR | B20: ARTURO RAMSES CONTRERAS TORRES | G20: 56473.56 | L20: 01/Mar/2026 | M20: Diario | N20: 230 | O20: Capacitaciones
A21: SIN CLASIFICAR | B21: AUTOMOVILES ESCANDINAVOS DEL CENTRO | G21: 28630.8 | L21: 01/Mar/2026 | M21: Diario | N21: 239 | O21: Mantenimiento y conservación
A22: Otros gastos generales | B22: BEPENSA LEASING | C22: GASTOS DE ADMINISTRACIÓN | D22: OTROS | G22: 114992.67 | L22: 01/Mar/2026 | M22: Diario | N22: 228 | O22: Arrendamiento a pers morales residtes nal
A23: Viaticos y gastos de viaje | B23: BOLETOS DE AVION | C23: COGS | G23: 246928.64 | L23: 01/Mar/2026 | M23: Diario | N23: 214 | O23: Boletos de Avión
A24: Gastos no deducibles | B24: BRENDA ELIZABETH REYES ROMERO | C24: OTROS INGRESOS / GASTOS | G24: 8500 | L24: 01/Mar/2026 | M24: Diario | N24: 234 | O24: Dictamenes
A25: Sueldos y salarios | B25: BRYTALAR CONSULTORES EN INGENIERIA Y OBRAS | G25: 4596.31 | L25: 01/Mar/2026 | M25: Diario | N25: 243 | O25: Servicios administrativos
A26: Sueldos y salarios | B26: BRYTALAR CONSULTORES EN INGENIERIA Y OBRAS | G26: 4598.08 | L26: 01/Mar/2026 | M26: Diario | N26: 243 | O26: Servicios administrativos
A27: Sueldos y salarios | B27: BRYTALAR CONSULTORES EN INGENIERIA Y OBRAS | G27: 4852.41 | L27: 01/Mar/2026 | M27: Diario | N27: 243 | O27: Servicios administrativos
A28: Sueldos y salarios | B28: BRYTALAR CONSULTORES EN INGENIERIA Y OBRAS | G28: 4852.41 | L28: 01/Mar/2026 | M28: Diario | N28: 243 | O28: Servicios administrativos
A29: Sueldos y salarios | B29: BRYTALAR CONSULTORES EN INGENIERIA Y OBRAS | G29: 6378.41 | L29: 01/Mar/2026 | M29: Diario | N29: 243 | O29: Servicios administrativos
A30: Sueldos y salarios | B30: BRYTALAR CONSULTORES EN INGENIERIA Y OBRAS | G30: 80776.28 | L30: 01/Mar/2026 | M30: Diario | N30: 243 | O30: Servicios administrativos
A31: Sueldos y salarios | B31: BRYTALAR CONSULTORES EN INGENIERIA Y OBRAS | G31: 81281.09 | L31: 01/Mar/2026 | M31: Diario | N31: 243 | O31: Servicios administrativos
A32: Honorarios a personas fis residentes nal | B32: CAMSA SOLUCIONES FISCALES | C32: GASTOS DE ADMINISTRACIÓN | D32: FINANZAS | G32: 11200 | L32: 01/Mar/2026 | M32: Diario | N32: 243 | O32: Servicios administrativos
A33: Honorarios a personas fis residentes nal | B33: CAMSA SOLUCIONES FISCALES | C33: GASTOS DE ADMINISTRACIÓN | D33: FINANZAS | G33: 21340.52 | L33: 01/Mar/2026 | M33: Diario | N33: 243 | O33: Servicios administrativos
A34: SIN CLASIFICAR | B34: CAPACITACIONES | G34: 9852 | L34: 01/Mar/2026 | M34: Diario | N34: 215 | O34: Capacitaciones
A35: SIN CLASIFICAR | B35: CARLOS GONZALEZ FLORES | G35: 6000 | L35: 01/Mar/2026 | M35: Diario | N35: 234 | O35: Dictamenes
A36: SIN CLASIFICAR | B36: CARLOS OBRYAN RAMIREZ GARZA | G36: 7700 | L36: 01/Mar/2026 | M36: Diario | N36: 234 | O36: Dictamenes
A37: Viaticos y gastos de viaje | B37: CASETAS | C37: COGS | G37: 66273.68 | L37: 01/Mar/2026 | M37: Diario | N37: 216 | O37: Casetas y estacionamientos
A38: SIN CLASIFICAR | B38: CESAR JAVIER RODRIGUEZ MONTIEL | G38: 13600 | L38: 01/Mar/2026 | M38: Diario | N38: 234 | O38: Dictamenes
A39: Combustibles y lubricantes | B39: COMBUSTIBLE | C39: COGS | D39: TÉCNICO | G39: =54349.86/2 -> 27174.93 | L39: 01/Mar/2026 | M39: Diario | N39: 217 | O39: Combustibles y lubricantes
A40: Combustibles y lubricantes | B40: COMBUSTIBLE | C40: COGS | D40: OPERACIONES | G40: =54349.86/2 -> 27174.93 | L40: 01/Mar/2026 | M40: Diario | N40: 217 | O40: Combustibles y lubricantes
...

Sheet nom_interna
B1: 1 de Enero del 2026 al 15 de Enero del 2026 Fecha de Pago : 15 de Enero del 2026 | H1: 16 de Enero del 2026 al 31 de Enero del 2026 Fecha de Pago : 31 de Enero del 2026
B3: Empleado | C3: Sueldo neto | D3: Area | H3: Empleado | I3: Sueldo neto | J3: Area
A4: 1 | B4: FRANCISCO JAVIER BERRUETA GUTIERREZ | C4: 5988.68 | D4: Otros | G4: 1 | H4: FRANCISCO JAVIER BERRUETA GUTIERREZ | I4: 5988.68 | J4: Otros
A5: 2 | B5: JOSE DE JESUS RAMIREZ GONZALEZ | C5: 12874.48 | D5: Aperaciones | G5: 2 | H5: JOSE DE JESUS RAMIREZ GONZALEZ | I5: 7253.28 | J5: Aperaciones
A6: 3 | B6: SUSANA RUTH GARCIA MARTINEZ | C6: 6499.95 | D6: Otros - LAE | G6: 3 | H6: SUSANA RUTH GARCIA MARTINEZ | I6: 6499.95 | J6: Otros - LAE
A7: 4 | B7: DIEGO JOSUE MALAGON MORALES | C7: 6499.95 | D7: Direccion | G7: 4 | H7: DIEGO JOSUE MALAGON MORALES | I7: 6499.95 | J7: Direccion
A8: 5 | B8: DIEGO GUERRA GUTIERREZ | C8: 6499.95 | D8: Otros - LAE | G8: 5 | H8: DIEGO GUERRA GUTIERREZ | I8: 6499.95 | J8: Otros - LAE
A9: 6 | B9: ALEJANDRO MORALES ROMERO | C9: 13123.05 | D9: Tecnico | G9: 6 | H9: ALEJANDRO MORALES ROMERO | I9: 13123.05 | J9: Tecnico
A10: 7 | B10: GINA ARLETTE DUARTE RODRIGUEZ | C10: 6499.95 | D10: Admon | G10: 7 | H10: GINA ARLETTE DUARTE RODRIGUEZ | I10: 6499.95 | J10: Admon
A11: 8 | B11: JOSE CARLOS SAENZ FERNANDEZ | C11: 8109.55 | D11: Admon | G11: 8 | H11: JOSE CARLOS SAENZ FERNANDEZ | I11: 8109.55 | J11: Admon
A12: 9 | B12: NADIA YURIT ARAUJO ISLAS | C12: 5192.95 | D12: Operaciones | G12: 9 | H12: NADIA YURIT ARAUJO ISLAS | I12: 0 | J12: Operaciones
A13: 10 | C13: =SUM(C4:C12) -> 71288.51 | I13: =SUM(I4:I12) -> 60474.36
A14: 11
B16: 1 de Febrero del 2026 al 15 de Febrero del 2026 Fecha de Pago : 13 de febrero del 2026 | H16: 16 de Febrero del 2026 al 28 de Febrero del 2026 Fecha de Pago : 27 de Febrero del 2026
B18: Empleado | C18: Sueldo neto | D18: Area
B19: FRANCISCO JAVIER BERRUETA GUTIERREZ | C19: 5989.43 | D19: Otros | H19: Empleado | I19: Sueldo neto | J19: Area
B20: JOSE DE JESUS RAMIREZ GONZALEZ | C20: 0 | D20: Aperaciones | G20: 1 | H20: FRANCISCO JAVIER BERRUETA GUTIERREZ | I20: 5989.43 | J20: Otros
B21: SUSANA RUTH GARCIA MARTINEZ | C21: 6499.95 | D21: Otros - LAE | G21: 2 | H21: JOSE DE JESUS RAMIREZ GONZALEZ | I21: 0 | J21: Aperaciones
B22: DIEGO JOSUE MALAGON MORALES | C22: 6499.95 | D22: Direccion | G22: 3 | H22: SUSANA RUTH GARCIA MARTINEZ | I22: 6499.95 | J22: Otros - LAE
B23: DIEGO GUERRA GUTIERREZ | C23: 6499.95 | D23: Otros - LAE | G23: 4 | H23: DIEGO JOSUE MALAGON MORALES | I23: 6499.95 | J23: Direccion
B24: ALEJANDRO MORALES ROMERO | C24: 13123.8 | D24: Tecnico | G24: 5 | H24: DIEGO GUERRA GUTIERREZ | I24: 6499.95 | J24: Otros - LAE
B25: GINA ARLETTE DUARTE RODRIGUEZ | C25: 6499.95 | D25: Admon | G25: 6 | H25: ALEJANDRO MORALES ROMERO | I25: 13123.8 | J25: Tecnico
B26: JOSE CARLOS SAENZ FERNANDEZ | C26: 11000.07 | D26: Admon | G26: 7 | H26: GINA ARLETTE DUARTE RODRIGUEZ | I26: 6499.95 | J26: Admon
B27: NADIA YURIT ARAUJO ISLAS | C27: 5193.7 | D27: Operaciones | G27: 8 | H27: JOSE CARLOS SAENZ FERNANDEZ | I27: 11000.07 | J27: Admon
C28: =SUM(C19:C27) -> 61306.8 | G28: 9 | H28: NADIA YURIT ARAUJO ISLAS | I28: 6988.79 | J28: Operaciones
G29: 10 | H29: -EDGARDO RAMIRO VIDAL CAMBERO | I29: 1575.2 | J29: Operaciones
G30: 11 | H30: -GERMAIN ACEVEDO LOPEZ | I30: 1575.2 | J30: Operaciones
G31: 12 | H31: -ALBA AMARIANA ARVIZU | I31: 1575.2 | J31: Operaciones
G32: 13 | H32: -NESTOR AXEL ESPINOSA MENDOZA | I32: 1575.2 | J32: Operaciones
G33: 14 | H33: -MARIANA GUADALUPE VILLEGAS BOLAÑO | I33: 1575.2 | J33: Operaciones
G34: 15 | H34: -IRIS SELENE HIDALGO JIMENEZ | I34: 1575.2 | J34: Operaciones
G35: 16 | H35: -EBER GALLARDO PADILLA | I35: 1575.2 | J35: Operaciones
G36: 17 | H36: -OMAR ANGEL RANGEL SANCHEZ | I36: 1575.2 | J36: Operaciones
I37: =SUM(I20:I36) -> 75703.49
B41: 1 de Marzo del 2026 al 15 de Marzo del 2026 Fecha de Pago : 13 de Marzo del 2026
H42: Empleado | I42: Sueldo neto | J42: Area
G43: 1 | H43: FRANCISCO JAVIER BERRUETA GUTIERREZ | I43: 5989.43 | J43: Otros
B44: Empleado | C44: Sueldo neto | D44: Area | G44: 2 | H44: JOSE DE JESUS RAMIREZ GONZALEZ | I44: 0 | J44: Aperaciones
A45: 1 | B45: FRANCISCO JAVIER BERRUETA GUTIERREZ | C45: 5989.43 | D45: Otros | G45: 3 | H45: SUSANA RUTH GARCIA MARTINEZ | I45: 6499.95 | J45: Otros - LAE | L45: =C116*2 -> 9451.2
A46: 2 | B46: JOSE DE JESUS RAMIREZ GONZALEZ | C46: 0 | D46: Aperaciones | G46: 4 | H46: DIEGO JOSUE MALAGON MORALES | I46: 6499.95 | J46: Direccion
...

Sheet respaldo otros egresos
A1: CATEGORIA_NETSUITE | B1: Concepto | C1: IS | D1: ÁREA | E1: ZONA PPTO | F1: EMPLEADO | G1: MONTO | H1: PERIODO | I1: AREA | J1: ZONA | K1: PCT_POND | L1: Cargos | M1: Fecha | N1: Tipo | O1: Número | P1: Clasf Efs | Q1: ID SGN | R1: PUESTO | S1: PAGADORA
A2: __EXCLUIR__ | B2: REVERSAS INGRESOS | G2: -619202.69 | L2: -619202.69 | M2: 31/Ene/2026 | N2: Diario | O2: 303 | P2: Diseño digital
A3: __EXCLUIR__ | B3: REVERSAS INGRESOS | G3: -33600 | L3: -33600 | M3: 31/Ene/2026 | N3: Diario | O3: 303 | P3: Diseño digital
A4: Agua | B4: MAGALI DESIREL RIOS NAVARROVIANEY MADERO CUADRAS | C4: GASTOS DE ADMINISTRACIÓN | D4: TÉCNICO | G4: 816.82222 | L4: 106 | M4: 01/Ene/2026 | N4: Diario | O4: 271 | P4: Agua
A5: Agua | B5: MAGALI DESIREL RIOS NAVARROVIANEY MADERO CUADRAS | C5: GASTOS DE ADMINISTRACIÓN | D5: RH | G5: 58.344444 | L5: 192 | M5: 01/Ene/2026 | N5: Diario | O5: 271 | P5: Agua
A6: Agua | B6: MAGALI DESIREL RIOS NAVARROVIANEY MADERO CUADRAS | C6: COGS | D6: OPERACIONES | G6: 1108.5444 | L6: 430 | M6: 01/Ene/2026 | N6: Diario | O6: 271 | P6: Agua
A7: Agua | B7: MAGALI DESIREL RIOS NAVARROVIANEY MADERO CUADRAS | C7: GASTOS DE ADMINISTRACIÓN | D7: FINANZAS | G7: 155.58519 | L7: 1897.5 | M7: 01/Ene/2026 | N7: Diario | O7: 271 | P7: Agua
A8: Agua | B8: MAGALI DESIREL RIOS NAVARROVIANEY MADERO CUADRAS | C8: GASTOS DE ADMINISTRACIÓN | D8: BRAND BUILDING | G8: 87.516667 | M8: 01/Ene/2026
A9: Agua | B9: MAGALI DESIREL RIOS NAVARROVIANEY MADERO CUADRAS | C9: GASTOS DE ADMINISTRACIÓN | D9: COMERCIAL | G9: 311.17037 | M9: 01/Ene/2026
A10: Agua | B10: MAGALI DESIREL RIOS NAVARROVIANEY MADERO CUADRAS | C10: GASTOS DE ADMINISTRACIÓN | D10: DIRECTIVO | G10: 87.516667 | M10: 01/Ene/2026
A11: Amortizacion acumulada de Software | B11: AMORTIZACION | C11: COGS | D11: OPERACIONES | F11: MONDAY | G11: 101529.4 | M11: 01/Ene/2026
A12: Amortizacion acumulada de Software | B12: AMORTIZACION | C12: GASTOS DE ADMINISTRACIÓN | D12: FINANZAS | F12: NETSUITE | G12: 101529.4 | M12: 01/Ene/2026
A13: Arrendamiento a pers fisicas residtes nal | B13: ANGEL OROSCO ANGELES | C13: POR CLASIFICAR | G13: 4258.36 | L13: 4258.36 | M13: 01/Ene/2026 | N13: Diario | O13: 272 | P13: Arrendamiento a pers físicas residtes nal
A14: Arrendamiento a pers fisicas residtes nal | B14: ANGEL OROSCO ANGELES | C14: POR CLASIFICAR | G14: 15365.54 | L14: 15365.54 | M14: 01/Ene/2026 | N14: Diario | O14: 272 | P14: Arrendamiento a pers morales residtes nal
A15: Arrendamiento a pers fisicas residtes nal | B15: ANGEL OROSCO ANGELES | C15: POR CLASIFICAR | G15: 17316.68 | L15: 17316.68 | M15: 01/Ene/2026 | N15: Diario | O15: 272 | P15: Arrendamiento a pers morales residtes nal
A16: Arrendamiento a pers morales residtes nal | B16: DELL LEASING MEXICO | C16: GASTOS DE ADMINISTRACIÓN | D16: TÉCNICO | G16: 15289.593 | L16: 3985.76 | M16: 01/Ene/2026 | N16: Diario | O16: 272 | P16: Arrendamiento a pers morales residtes nal
A17: Arrendamiento a pers morales residtes nal | B17: DELL LEASING MEXICO | C17: GASTOS DE ADMINISTRACIÓN | D17: RH | G17: 1092.1138 | L17: 4172.27 | M17: 01/Ene/2026 | N17: Diario | O17: 272 | P17: Arrendamiento a pers morales residtes nal
A18: Arrendamiento a pers morales residtes nal | B18: DELL LEASING MEXICO | C18: COGS | D18: OPERACIONES | G18: 20750.162 | L18: 4578.49 | M18: 01/Ene/2026 | N18: Diario | O18: 272 | P18: Arrendamiento a pers morales residtes nal
A19: Arrendamiento a pers morales residtes nal | B19: DELL LEASING MEXICO | C19: GASTOS DE ADMINISTRACIÓN | D19: FINANZAS | G19: 2912.3034 | L19: 6890.7 | M19: 01/Ene/2026 | N19: Diario | O19: 272 | P19: Arrendamiento a pers morales residtes nal
A20: Arrendamiento a pers morales residtes nal | B20: DELL LEASING MEXICO | C20: GASTOS DE ADMINISTRACIÓN | D20: BRAND BUILDING | G20: 1638.1707 | L20: 7734.15 | M20: 01/Ene/2026 | N20: Diario | O20: 272 | P20: Arrendamiento a pers morales residtes nal
A21: Arrendamiento a pers morales residtes nal | B21: DELL LEASING MEXICO | C21: GASTOS DE ADMINISTRACIÓN | D21: COMERCIAL | G21: 5824.6068 | L21: 9987.58 | M21: 01/Ene/2026 | N21: Diario | O21: 272 | P21: Arrendamiento a pers morales residtes nal
A22: Arrendamiento a pers morales residtes nal | B22: DELL LEASING MEXICO | C22: GASTOS DE ADMINISTRACIÓN | D22: DIRECTIVO | G22: 1638.1707 | L22: 11796.17 | M22: 01/Ene/2026 | N22: Diario | O22: 272 | P22: Arrendamiento a pers morales residtes nal
A23: Arrendamiento a pers morales residtes nal | B23: EXI TECNOLOGIAS DE LA INFORMACION | C23: POR CLASIFICAR | G23: 11900 | L23: 11900 | M23: 01/Ene/2026 | N23: Diario | O23: 272 | P23: Arrendamiento a pers morales residtes nal
A24: Arrendamiento a pers morales residtes nal | B24: FLEET CAR COMPANY MX | C24: COGS | D24: OPERACIONES | G24: 2392.85 | L24: 2392.85 | M24: 01/Ene/2026 | N24: Diario | O24: 272 | P24: Arrendamiento a pers morales residtes nal
A25: Arrendamiento a pers morales residtes nal | B25: FLEET CAR COMPANY MX | C25: COGS | D25: OPERACIONES | G25: 2758.62 | L25: 2758.62 | M25: 01/Ene/2026 | N25: Diario | O25: 272 | P25: Arrendamiento a pers morales residtes nal
A26: Arrendamiento a pers morales residtes nal | B26: FLEET CAR COMPANY MX | C26: COGS | D26: OPERACIONES | G26: 5475.37 | L26: 5475.37 | M26: 01/Ene/2026 | N26: Diario | O26: 272 | P26: Arrendamiento a pers morales residtes nal
A27: Arrendamiento a pers morales residtes nal | B27: PS GRAPH | C27: GASTOS DE ADMINISTRACIÓN | D27: TÉCNICO | G27: 145600 | M27: 01/Ene/2026 | N27: Diario | O27: 272 | P27: Arrendamiento a pers morales residtes nal
A28: Arrendamiento a pers morales residtes nal | B28: PS GRAPH | C28: GASTOS DE ADMINISTRACIÓN | D28: RH | G28: 10400 | M28: 01/Ene/2026 | N28: Diario | O28: 272 | P28: Arrendamiento a pers morales residtes nal
A29: Arrendamiento a pers morales residtes nal | B29: PS GRAPH | C29: COGS | D29: OPERACIONES | E29: CENTRO | G29: 197600 | M29: 01/Ene/2026 | N29: Diario | O29: 272 | P29: Arrendamiento a pers morales residtes nal
A30: Arrendamiento a pers morales residtes nal | B30: PS GRAPH | C30: GASTOS DE ADMINISTRACIÓN | D30: FINANZAS | G30: 27733.333 | M30: 01/Ene/2026
A31: Arrendamiento a pers morales residtes nal | B31: PS GRAPH | C31: GASTOS DE ADMINISTRACIÓN | D31: BRAND BUILDING | G31: 15600 | M31: 01/Ene/2026
A32: Arrendamiento a pers morales residtes nal | B32: PS GRAPH | C32: GASTOS DE ADMINISTRACIÓN | D32: COMERCIAL | G32: 55466.667 | M32: 01/Ene/2026
A33: Arrendamiento a pers morales residtes nal | B33: PS GRAPH | C33: GASTOS DE ADMINISTRACIÓN | D33: DIRECTIVO | G33: 15600 | M33: 01/Ene/2026
A34: Arrendamiento a pers morales residtes nal | B34: LOC BOX | C34: COGS | D34: OPERACIONES | G34: 4346.25 | L34: 4346.25 | M34: 01/Ene/2026 | N34: Diario | O34: 275 | P34: Casetas y estacionamientos
A35: Arrendamiento a pers morales residtes nal | B35: RESCUE 24 ASISTENCIA VIAL INTELIGENTE | C35: COGS | D35: OPERACIONES | G35: 4456 | L35: 4456 | M35: 01/Ene/2026 | N35: Diario | O35: 293 | P35: Viáticos uber/taxi
A36: Arrendamiento a pers morales residtes nal | B36: RESCUE 24 ASISTENCIA VIAL INTELIGENTE | C36: COGS | D36: OPERACIONES | G36: 4456 | L36: 4456 | M36: 01/Ene/2026 | N36: Diario | O36: 293 | P36: Viáticos uber/taxi
A37: Arrendamiento a personas fisicas resid nal | B37: FELIPE DE JESUS ORGANISTA ZAVALA | C37: POR CLASIFICAR | G37: 19503.8 | L37: 19503.8 | M37: 01/Ene/2026 | N37: Diario | O37: 272 | P37: Arrendamiento a pers morales residtes nal
A38: Arrendamiento a personas fisicas resid nal | B38: GUILLERMO ALBERTO MENDEZ ROMERO | C38: COGS | F38: ARRENDAMIENTO OFICINAS MONTERREY | G38: 17306.48 | L38: 17306.48 | M38: 01/Ene/2026 | N38: Diario | O38: 272 | P38: Arrendamiento a pers morales residtes nal
A39: Arrendamiento a personas fisicas resid nal | B39: EDGAR ALONSO AGUILAR NEGRETE | C39: GASTOS DE ADMINISTRACIÓN | D39: TÉCNICO | G39: 4275 | L39: 4275 | M39: 01/Ene/2026 | N39: Diario | O39: 276 | P39: Cuotas y suscripciones
A40: Arrendamiento Automotriz | B40: VOLKSWAGEN | C40: COGS | D40: OPERACIONES | G40: =20826.33*70% -> 14578.431 | L40: 20826.33 | M40: 01/Ene/2026 | N40: Diario | O40: 272 | P40: Arrendamiento a pers morales residtes nal
...

Sheet respaldo sueldos y salarios
A1: CATEGORIA_NETSUITE | B1: Concepto | C1: IS | D1: ÁREA | E1: ZONA PPTO | F1: EMPLEADO | G1: MONTO | H1: PERIODO | I1: AREA | J1: ZONA | K1: PCT_POND | L1: Cargos | M1: Fecha | N1: Tipo | O1: Número | P1: Clasf Efs | Q1: ID SGN | R1: PUESTO | S1: PAGADORA
A2: Sueldos y salarios | B2: ACEVEDO LOPEZ GERMAIN | C2: COGS | D2: OPERACIONES | E2: CENTRO | F2: GERMAIN ACEVEDO LOPEZ | G2: 12269.305 | H2: ENERO
A3: Sueldos y salarios | B3: ACEVEDO LOPEZ GERMAIN | C3: COGS | D3: OPERACIONES | E3: CENTRO | F3: GERMAIN ACEVEDO LOPEZ | G3: 12620.03 | H3: MARZO
A4: Sueldos y salarios | B4: ACEVEDO LOPEZ GERMAIN | C4: COGS | D4: OPERACIONES | E4: CENTRO | F4: GERMAIN ACEVEDO LOPEZ | G4: 10861.391 | H4: FEBRERO
A5: Sueldos y salarios | B5: ACEVEDO LOPEZ GERMAIN | C5: COGS | D5: OPERACIONES | E5: CENTRO | F5: GERMAIN ACEVEDO LOPEZ | G5: 10842.303 | H5: ABRIL
A6: Sueldos y salarios | B6: AGUILAR MORALES EMANUEL | C6: COGS | D6: OPERACIONES | E6: CENTRO | F6: EMANUEL AGUILAR MORALES | G6: 24075.35 | H6: MARZO
A7: Sueldos y salarios | B7: AGUILAR MORALES EMANUEL | C7: COGS | D7: OPERACIONES | E7: CENTRO | F7: EMANUEL AGUILAR MORALES | G7: 14312.507 | H7: FEBRERO
A8: Sueldos y salarios | B8: ALCANTARA SEGURA MIRIAM JOSEFINA | C8: GASTOS DE ADMINISTRACIÓN | D8: TÉCNICO | F8: MIRIAM JOSEFINA ALCANTARA SEGURA | G8: 14378.848 | H8: ENERO
A9: Sueldos y salarios | B9: ALCANTARA SEGURA MIRIAM JOSEFINA | C9: GASTOS DE ADMINISTRACIÓN | D9: TÉCNICO | F9: MIRIAM JOSEFINA ALCANTARA SEGURA | G9: 15993.283 | H9: MARZO
A10: Sueldos y salarios | B10: ALCANTARA SEGURA MIRIAM JOSEFINA | C10: GASTOS DE ADMINISTRACIÓN | D10: TÉCNICO | F10: MIRIAM JOSEFINA ALCANTARA SEGURA | G10: 15770.154 | H10: FEBRERO
A11: Sueldos y salarios | B11: ALMADA NOZATO DANNA PAOLA | C11: COGS | D11: OPERACIONES | E11: PEPSICO SE | F11: DANNA PAOLA ALMADA NOZATO | G11: 13779.069 | H11: MARZO
A12: Sueldos y salarios | B12: ALMADA NOZATO DANNA PAOLA | C12: COGS | D12: OPERACIONES | E12: PEPSICO SE | F12: DANNA PAOLA ALMADA NOZATO | G12: 13493.097 | H12: FEBRERO
A13: Sueldos y salarios | B13: ALMADA NOZATO DANNA PAOLA | C13: COGS | D13: OPERACIONES | E13: PEPSICO SE | F13: DANNA PAOLA ALMADA NOZATO | G13: 13751.394 | H13: ENERO
A14: Sueldos y salarios | B14: ALMANZA GUZMAN FREDDY JESUS | C14: GASTOS DE ADMINISTRACIÓN | D14: BRAND BUILDING | F14: FREDDY JESUS ALMANZA GUZMAN | G14: 19234.553 | H14: ENERO
A15: Sueldos y salarios | B15: ALMANZA GUZMAN FREDDY JESUS | C15: GASTOS DE ADMINISTRACIÓN | D15: BRAND BUILDING | F15: FREDDY JESUS ALMANZA GUZMAN | G15: 23356.679 | H15: MARZO
A16: Sueldos y salarios | B16: ALMANZA GUZMAN FREDDY JESUS | C16: GASTOS DE ADMINISTRACIÓN | D16: BRAND BUILDING | F16: FREDDY JESUS ALMANZA GUZMAN | G16: 18896.204 | H16: FEBRERO
A17: Sueldos y salarios | B17: ALTAMIRANO DIAZ CIELO ANEL | C17: COGS | D17: OPERACIONES | E17: NOROESTE | F17: CIELO ANEL ALTAMIRANO DIAZ | G17: 11487.986 | H17: MARZO
A18: Sueldos y salarios | B18: ALTAMIRANO DIAZ CIELO ANEL | C18: COGS | D18: OPERACIONES | E18: NOROESTE | F18: CIELO ANEL ALTAMIRANO DIAZ | G18: 17785.736 | H18: FEBRERO
A19: Sueldos y salarios | B19: ALTAMIRANO DIAZ CIELO ANEL | C19: COGS | D19: OPERACIONES | E19: NOROESTE | F19: CIELO ANEL ALTAMIRANO DIAZ | G19: 18125.363 | H19: ENERO
A20: Sueldos y salarios | B20: ALVAREZ CABRERA RODRIGO | C20: COGS | D20: OPERACIONES | E20: OCCIDENTE | F20: RODRIGO ALVAREZ CABRERA | G20: 19431.204 | H20: FEBRERO
A21: Sueldos y salarios | B21: ALVAREZ CABRERA RODRIGO | C21: COGS | D21: OPERACIONES | E21: OCCIDENTE | F21: RODRIGO ALVAREZ CABRERA | G21: 19779.553 | H21: ENERO
A22: Sueldos y salarios | B22: ALVAREZ CABRERA RODRIGO | C22: COGS | D22: OPERACIONES | E22: OCCIDENTE | F22: RODRIGO ALVAREZ CABRERA | G22: 15802.44 | H22: MARZO
A23: Sueldos y salarios | B23: ALVAREZ CABRERA RODRIGO | C23: COGS | D23: OPERACIONES | E23: OCCIDENTE | F23: RODRIGO ALVAREZ CABRERA | G23: 10060.44 | H23: ABRIL
A24: Sueldos y salarios | B24: ALVAREZ CHAVEZ VICTOR MANUEL | C24: GASTOS DE ADMINISTRACIÓN | D24: COMERCIAL | F24: VICTOR MANUEL ALVAREZ CHAVEZ | G24: 18848.226 | H24: FEBRERO
A25: Sueldos y salarios | B25: ALVAREZ CHAVEZ VICTOR MANUEL | C25: GASTOS DE ADMINISTRACIÓN | D25: COMERCIAL | F25: VICTOR MANUEL ALVAREZ CHAVEZ | G25: 19080.558 | H25: MARZO
A26: Sueldos y salarios | B26: ALVAREZ CHAVEZ VICTOR MANUEL | C26: GASTOS DE ADMINISTRACIÓN | D26: COMERCIAL | F26: VICTOR MANUEL ALVAREZ CHAVEZ | G26: 19207.063 | H26: ENERO
A27: Sueldos y salarios | B27: AREVALO CERVANTES MIGUEL ANGEL | C27: GASTOS DE ADMINISTRACIÓN | D27: BRAND BUILDING | F27: MIGUEL ANGEL AREVALO CERVANTES | G27: 20193.283 | H27: MARZO
A28: Sueldos y salarios | B28: AREVALO CERVANTES MIGUEL ANGEL | C28: GASTOS DE ADMINISTRACIÓN | D28: BRAND BUILDING | F28: MIGUEL ANGEL AREVALO CERVANTES | G28: 20050.154 | H28: FEBRERO
A29: Sueldos y salarios | B29: AREVALO CERVANTES MIGUEL ANGEL | C29: GASTOS DE ADMINISTRACIÓN | D29: BRAND BUILDING | F29: MIGUEL ANGEL AREVALO CERVANTES | G29: 20427.175 | H29: ENERO
A30: Sueldos y salarios | B30: ARRAZOLA SANTAELLA ALBERTO NICOLAS | C30: COGS | D30: OPERACIONES | E30: SURESTE | F30: ALBERTO NICOLAS ARRAZOLA SANTAELLA | G30: 8107.3609 | H30: FEBRERO
A31: Sueldos y salarios | B31: ARRAZOLA SANTAELLA ALBERTO NICOLAS | C31: COGS | D31: OPERACIONES | E31: SURESTE | F31: ALBERTO NICOLAS ARRAZOLA SANTAELLA | G31: 20303.011 | H31: MARZO
A32: Sueldos y salarios | B32: ARRAZOLA SANTAELLA ALBERTO NICOLAS | C32: COGS | D32: OPERACIONES | E32: SURESTE | F32: ALBERTO NICOLAS ARRAZOLA SANTAELLA | G32: 18427.44 | H32: ABRIL
A33: Sueldos y salarios | B33: ARREOLA ALATRISTE ALEXANDRA ESTEPHANIA | C33: COGS | D33: TÉCNICO | F33: ALEXANDRA ESTEPHANIA ARREOLA ALATRISTE | G33: 13202.829 | H33: MARZO
A34: Sueldos y salarios | B34: ARREOLA ALATRISTE ALEXANDRA ESTEPHANIA | C34: COGS | D34: TÉCNICO | F34: ALEXANDRA ESTEPHANIA ARREOLA ALATRISTE | G34: 10059.743 | H34: FEBRERO
A35: Sueldos y salarios | B35: ARREOLA ALATRISTE ALEXANDRA ESTEPHANIA | C35: COGS | D35: TÉCNICO | F35: ALEXANDRA ESTEPHANIA ARREOLA ALATRISTE | G35: 7350 | H35: ENERO
A36: Sueldos y salarios | B36: ARVIZU ESTRADA ALBA MARIANA | C36: COGS | D36: OPERACIONES | E36: CENTRO | F36: ALBA MARIANA ARVIZU ESTRADA | G36: 15770.03 | H36: MARZO
A37: Sueldos y salarios | B37: ARVIZU ESTRADA ALBA MARIANA | C37: COGS | D37: OPERACIONES | E37: CENTRO | F37: ALBA MARIANA ARVIZU ESTRADA | G37: 14071.391 | H37: FEBRERO
A38: Sueldos y salarios | B38: ARVIZU ESTRADA ALBA MARIANA | C38: COGS | D38: OPERACIONES | E38: CENTRO | F38: ALBA MARIANA ARVIZU ESTRADA | G38: 3209.1708 | H38: ENERO
A39: Sueldos y salarios | B39: ARVIZU ESTRADA ALBA MARIANA | C39: COGS | D39: OPERACIONES | E39: CENTRO | F39: ALBA MARIANA ARVIZU ESTRADA | G39: 15277.44 | H39: ABRIL
A40: Sueldos y salarios | B40: BACA AGUIRRE ANTONIO | C40: COGS | D40: OPERACIONES | E40: NOROESTE | F40: ANTONIO BACA AGUIRRE | G40: 17823.58 | H40: FEBRERO
...

Sheet Sheet2
A1: CATEGORIA_NETSUITE | B1: Concepto | C1: IS | D1: ÁREA | E1: ZONA PPTO | F1: EMPLEADO | G1: MONTO | H1: PERIODO | I1: AREA | J1: ZONA | K1: PCT_POND | L1: Cargos | M1: Fecha | N1: Tipo | O1: Número | P1: Clasf Efs | Q1: ID SGN | R1: PUESTO | S1: PAGADORA
A2: Sueldos y salarios | B2: ACEVEDO LOPEZ GERMAIN | C2: COGS | D2: OPERACIONES | E2: CENTRO | F2: GERMAIN ACEVEDO LOPEZ | G2: 12269.305 | H2: ENERO
A3: Sueldos y salarios | B3: ACEVEDO LOPEZ GERMAIN | C3: COGS | D3: OPERACIONES | E3: CENTRO | F3: GERMAIN ACEVEDO LOPEZ | G3: =2676.24+nom_interna!C55+nom_interna!I53 -> 12620.03 | H3: MARZO
A4: Sueldos y salarios | B4: ACEVEDO LOPEZ GERMAIN | C4: COGS | D4: OPERACIONES | E4: CENTRO | F4: GERMAIN ACEVEDO LOPEZ | G4: =9286.191037+nom_interna!I30 -> 10861.391 | H4: FEBRERO
A5: Sueldos y salarios | B5: ACEVEDO LOPEZ GERMAIN | C5: COGS | D5: OPERACIONES | E5: CENTRO | F5: GERMAIN ACEVEDO LOPEZ | G5: =1391.103+nom_interna!C107+nom_interna!I107 -> 10842.303 | H5: ABRIL
A6: Sueldos y salarios | B6: AGUILAR MORALES EMANUEL | C6: COGS | D6: OPERACIONES | E6: CENTRO | F6: EMANUEL AGUILAR MORALES | G6: 24075.35 | H6: MARZO
A7: Sueldos y salarios | B7: AGUILAR MORALES EMANUEL | C7: COGS | D7: OPERACIONES | E7: CENTRO | F7: EMANUEL AGUILAR MORALES | G7: 14312.507 | H7: FEBRERO
